Workbook
Name Check2: Check[[#All],[סימון2]:[סטטוס גמר ]]
Name PHL: 'מטריצת סטטוס עם מעליות'!$Y$11:$AA$18,'מטריצת סטטוס עם מעליות'!$AY$11:$BG$18
Name PHR: 'מטריצת סטטוס עם מעליות'!$H$11:$O$18,'מטריצת סטטוס עם מעליות'!$AO$11:$AP$18
Name Sold: Table1[]
Name Sold: Table1[]
Name Sold1: Table1[]
Name Tower: Table4[#All]
Name Tower: Table4[#All]

Sheet מטריצת סטטוס עם מעליות
A1: פרויקט סמל דרום DUO TLV | BP1: עמודה1
A2: סטטוס דירות מכורות - 14/04/2025 | BP2: עמודה1
BP3: כותרות
L4: מגדל דרומי (2) | AO4: מגדל צפוני (1) | BP4: כותרות
B5: TS | C5: TS | D5: TS | E5: TS | F5: TS | G5: TS | H5: TS | J5: TS | K5: TS | L5: TS | M5: TS | N5: TS | O5: TS | P5: TS | Q5: TS | R5: TS | S5: TS | T5: TS | U5: TS | V5: TS | W5: TS | X5: TS | Y5: TS | Z5: TS | AA5: TS | AB5: TS | AC5: TS | AD5: TS | AE5: TS | AF5: TS | AG5: TS | AI5: TN | AJ5: TN | AK5: TN | AL5: TN | AM5: TN | AN5: TN | AO5: TN | AP5: TN | AQ5: TN | AR5: TN | AS5: TN | AT5: TN | AU5: TN | AV5: TN | AW5: TN | AX5: TN | AY5: TN | BA5: TN | BB5: TN | BC5: TN | BD5: TN | BE5: TN | BF5: TN | BG5: TN | BH5: TN | BI5: TN | BJ5: TN | BK5: TN | BL5: TN | BM5: TN | BP5: כותרות
AH6: מקרא | BP6: כותרות
A7: דירה בקומה | B7: =_xlfn.CONCAT("קומה ",B8) -> קומה 50 | C7: דירה | D7: H-S | E7: G-S | F7: F-S | G7: E-S | H7: 337 | AO7: 331 | BH7: E-N | BI7: F-N | BJ7: G-N | BK7: H-N | BL7: דירה | BM7: =_xlfn.CONCAT("קומה ",BM8) -> קומה 50 | BN7: דירה בקומה | BP7: דירה
B8: =B12+1 -> 50 | C8: סטטוס | H8: =VLOOKUP("*"&H$5&".Ap."&H7,Check[],1,FALSE) -> O.PH5.TS.Ap.337 | I8: =H8 -> O.PH5.TS.Ap.337 | J8: =I8 -> O.PH5.TS.Ap.337 | K8: =J8 -> O.PH5.TS.Ap.337 | L8: =K8 -> O.PH5.TS.Ap.337 | M8: =L8 -> O.PH5.TS.Ap.337 | N8: =M8 -> O.PH5.TS.Ap.337 | O8: =N8 -> O.PH5.TS.Ap.337 | P8: =O8 -> O.PH5.TS.Ap.337 | ... V8: =U8 -> O.PH5.TS.Ap.337 | W8: =U8 -> O.PH5.TS.Ap.337 | X8: =V8 -> O.PH5.TS.Ap.337 | Y8: =X8 -> O.PH5.TS.Ap.337 | Z8: =X8 -> O.PH5.TS.Ap.337 | AA8: =Y8 -> O.PH5.TS.Ap.337 | AE8: S.2.1 | AF8: S.3.1 | AG8: S.4.1 | AH8: P.4.1 | AI8: S.5.1 | AJ8: P.5.1 | AK8: PH.1 | AO8: =VLOOKUP("*"&AO$5&".Ap."&AO7,Check[],1,FALSE) -> S.PH5.TN.Ap.331 | AP8: =AO8 -> S.PH5.TN.Ap.331 | AQ8: =AP8 -> S.PH5.TN.Ap.331 | AR8: =AQ8 -> S.PH5.TN.Ap.331 | AS8: =AR8 -> S.PH5.TN.Ap.331 | AT8: =AS8 -> S.PH5.TN.Ap.331 | AU8: =AT8 -> S.PH5.TN.Ap.331 | AV8: =AU8 -> S.PH5.TN.Ap.331 | AW8: =AV8 -> S.PH5.TN.Ap.331 | ... BG8: =BF8 -> S.PH5.TN.Ap.331 | BL8: סטטוס | BM8: =BM12+1 -> 50 | BP8: סטטוס
C9: # צל | H9: =VLOOKUP(H8,Check[],5,FALSE) -> 337 | AE9: 2 חד' | AF9: 3 חד' | AG9: 4 חד' | AH9: 4 חד' | AI9: 5 חד' | AJ9: 5 חד' | AK9: פנטהאוס | AO9: =VLOOKUP(AO8,Check[],5,FALSE) -> 331 | BL9: # צל | BP9: צל
B10: =B14+4 -> 183.48 | C10: טיפוס | H10: =VLOOKUP(H8,Check[],6,FALSE) -> 5001 | AE10: סטנדרט | AF10: סטנדרט | AG10: סטנדרט | AH10: פרימיום | AI10: סטנדרט | AJ10: פרימיום | AO10: =VLOOKUP(AO8,Check[],6,FALSE) -> 5001 | BL10: טיפוס | BM10: =BM14+4 -> 183.48 | BP10: טיפוס
A11: 2 דירות בקומה | B11: =_xlfn.CONCAT("קומה ",B12) -> קומה 49 | C11: דירה | D11: אלונקה | E11: כבאים | H11: 336 | P11: 335 | Y11: 336 | AE11: בעלים | AF11: בעלים | AG11: בעלים | AH11: בעלים | AI11: בעלים | AJ11: בעלים | AK11: בעלים | AO11: 330 | AQ11: 329 | AY11: 330 | BJ11: כבאים | BK11: אלונקה | BL11: דירה | BM11: =_xlfn.CONCAT("קומה ",BM12) -> קומה 49 | BN11: 2 דירות בקומה | BP11: דירה
B12: =B16+1 -> 49 | C12: סטטוס | H12: =VLOOKUP("*"&H$5&".Ap."&H11,Check[],1,FALSE) -> O.PH4.TS.Ap.336 | J12: =H12 -> O.PH4.TS.Ap.336 | K12: =J12 -> O.PH4.TS.Ap.336 | L12: =K12 -> O.PH4.TS.Ap.336 | M12: =L12 -> O.PH4.TS.Ap.336 | N12: =M12 -> O.PH4.TS.Ap.336 | O12: =N12 -> O.PH4.TS.Ap.336 | P12: =VLOOKUP("*"&P$5&".Ap."&P11,Check[],1,FALSE) -> O.PH3.TS.Ap.335 | Q12: =P12 -> O.PH3.TS.Ap.335 | R12: =Q12 -> O.PH3.TS.Ap.335 | S12: =R12 -> O.PH3.TS.Ap.335 | T12: =S12 -> O.PH3.TS.Ap.335 | U12: =T12 -> O.PH3.TS.Ap.335 | V12: =U12 -> O.PH3.TS.Ap.335 | W12: =U12 -> O.PH3.TS.Ap.335 | X12: =V12 -> O.PH3.TS.Ap.335 | Y12: =VLOOKUP("*"&Y$5&".Ap."&Y11,Check[],1,FALSE) -> O.PH4.TS.Ap.336 | Z12: =X12 -> O.PH3.TS.Ap.335 | AA12: =Y12 -> O.PH4.TS.Ap.336 | AE12: o.s.2 | AF12: o.s.3 | AG12: o.s.4 | AH12: o.p.4 | AI12: o.s.5 | AJ12: o.p.5 | AK12: o.ph | AO12: =VLOOKUP("*"&AO$5&".Ap."&AO11,Check[],1,FALSE) -> V.GM.PH4.TN.Ap.330 | AP12: =AO12 -> V.GM.PH4.TN.Ap.330 | AQ12: =VLOOKUP("*"&AQ$5&".Ap."&AQ11,Check[],1,FALSE) -> V.GM.PH3.TN.Ap.329 | AR12: =AQ12 -> V.GM.PH3.TN.Ap.329 | AS12: =AR12 -> V.GM.PH3.TN.Ap.329 | AT12: =AS12 -> V.GM.PH3.TN.Ap.329 | AU12: =AT12 -> V.GM.PH3.TN.Ap.329 | AV12: =AU12 -> V.GM.PH3.TN.Ap.329 | AW12: =AV12 -> V.GM.PH3.TN.Ap.329 | AX12: =AW12 -> V.GM.PH3.TN.Ap.329 | AY12: =VLOOKUP("*"&AY$5&".Ap."&AY11,Check[],1,FALSE) -> V.GM.PH4.TN.Ap.330 | BA12: =AY12 -> V.GM.PH4.TN.Ap.330 | BB12: =BA12 -> V.GM.PH4.TN.Ap.330 | BC12: =BB12 -> V.GM.PH4.TN.Ap.330 | BD12: =BC12 -> V.GM.PH4.TN.Ap.330 | BE12: =BD12 -> V.GM.PH4.TN.Ap.330 | BF12: =BE12 -> V.GM.PH4.TN.Ap.330 | BL12: סטטוס | BM12: =BM16+1 -> 49 | BP12: סטטוס
C13: # צל | H13: =VLOOKUP(H12,Check[],5,FALSE) -> 336 | P13: =VLOOKUP(P12,Check[],5,FALSE) -> 335 | Y13: =VLOOKUP(Y12,Check[],5,FALSE) -> 336 | AE13: מכורה | AF13: מכורה | AG13: מכורה | AH13: מכורה | AI13: מכורה | AJ13: מכורה | AK13: מכורה | AO13: =VLOOKUP(AO12,Check[],5,FALSE) -> 330 | AQ13: =VLOOKUP(AQ12,Check[],5,FALSE) -> 329 | AY13: =VLOOKUP(AY12,Check[],5,FALSE) -> 330 | BL13: # צל | BP13: צל
B14: =B18+4 -> 179.48 | C14: טיפוס | H14: =VLOOKUP(H12,Check[],6,FALSE) -> 4901 | P14: =VLOOKUP(P12,Check[],6,FALSE) -> 4902 | Y14: =VLOOKUP(Y12,Check[],6,FALSE) -> 4901 | AO14: =VLOOKUP(AO12,Check[],6,FALSE) -> 4901 | AQ14: =VLOOKUP(AQ12,Check[],6,FALSE) -> 4902 | AY14: =VLOOKUP(AY12,Check[],6,FALSE) -> 4901 | BL14: טיפוס | BM14: =BM18+4 -> 179.48 | BP14: טיפוס
B15: =_xlfn.CONCAT("קומה ",B16) -> קומה 48 | C15: דירה | H15: 334 | P15: 333 | Y15: 334 | AE15: פנויה | AF15: פנויה | AG15: פנויה | AH15: פנויה | AI15: פנויה | AJ15: פנויה | AK15: פנויה | AO15: 328 | AQ15: 327 | AY15: 328 | BL15: דירה | BM15: =_xlfn.CONCAT("קומה ",BM16) -> קומה 48 | BP15: דירה
B16: =B20+1 -> 48 | C16: סטטוס | H16: =VLOOKUP("*"&H$5&".Ap."&H15,Check[],1,FALSE) -> V.GM.PH2.TS.Ap.334 | J16: =H16 -> V.GM.PH2.TS.Ap.334 | K16: =J16 -> V.GM.PH2.TS.Ap.334 | L16: =K16 -> V.GM.PH2.TS.Ap.334 | M16: =L16 -> V.GM.PH2.TS.Ap.334 | N16: =M16 -> V.GM.PH2.TS.Ap.334 | O16: =N16 -> V.GM.PH2.TS.Ap.334 | P16: =VLOOKUP("*"&P$5&".Ap."&P15,Check[],1,FALSE) -> V.GM.PH1.TS.Ap.333 | Q16: =P16 -> V.GM.PH1.TS.Ap.333 | R16: =Q16 -> V.GM.PH1.TS.Ap.333 | S16: =R16 -> V.GM.PH1.TS.Ap.333 | T16: =S16 -> V.GM.PH1.TS.Ap.333 | U16: =T16 -> V.GM.PH1.TS.Ap.333 | V16: =U16 -> V.GM.PH1.TS.Ap.333 | W16: =U16 -> V.GM.PH1.TS.Ap.333 | X16: =V16 -> V.GM.PH1.TS.Ap.333 | Y16: =VLOOKUP("*"&Y$5&".Ap."&Y15,Check[],1,FALSE) -> V.GM.PH2.TS.Ap.334 | Z16: =X16 -> V.GM.PH1.TS.Ap.333 | AA16: =Y16 -> V.GM.PH2.TS.Ap.334 | AE16: v.s.2 | AF16: v.s.3 | AG16: v.s.4 | AH16: v.p.4 | AI16: v.s.5 | AJ16: v.p.5 | AK16: v.ph | AO16: =VLOOKUP("*"&AO$5&".Ap."&AO15,Check[],1,FALSE) -> V.GM.PH2.TN.Ap.328 | AP16: =AO16 -> V.GM.PH2.TN.Ap.328 | AQ16: =VLOOKUP("*"&AQ$5&".Ap."&AQ15,Check[],1,FALSE) -> V.GM.PH1.TN.Ap.327 | AR16: =AQ16 -> V.GM.PH1.TN.Ap.327 | AS16: =AR16 -> V.GM.PH1.TN.Ap.327 | AT16: =AS16 -> V.GM.PH1.TN.Ap.327 | AU16: =AT16 -> V.GM.PH1.TN.Ap.327 | AV16: =AU16 -> V.GM.PH1.TN.Ap.327 | AW16: =AV16 -> V.GM.PH1.TN.Ap.327 | AX16: =AW16 -> V.GM.PH1.TN.Ap.327 | AY16: =VLOOKUP("*"&AY$5&".Ap."&AY15,Check[],1,FALSE) -> V.GM.PH2.TN.Ap.328 | BA16: =AY16 -> V.GM.PH2.TN.Ap.328 | BB16: =BA16 -> V.GM.PH2.TN.Ap.328 | BC16: =BB16 -> V.GM.PH2.TN.Ap.328 | BD16: =BC16 -> V.GM.PH2.TN.Ap.328 | BE16: =BD16 -> V.GM.PH2.TN.Ap.328 | BF16: =BE16 -> V.GM.PH2.TN.Ap.328 | BL16: סטטוס | BM16: =BM20+1 -> 48 | BP16: סטטוס
C17: # צל | H17: =VLOOKUP(H16,Check[],5,FALSE) -> 334 | P17: =VLOOKUP(P16,Check[],5,FALSE) -> 333 | Y17: =VLOOKUP(Y16,Check[],5,FALSE) -> 334 | AO17: =VLOOKUP(AO16,Check[],5,FALSE) -> 328 | AQ17: =VLOOKUP(AQ16,Check[],5,FALSE) -> 327 | AY17: =VLOOKUP(AY16,Check[],5,FALSE) -> 328 | BL17: # צל | BP17: צל
B18: =B22+3.84 -> 175.48 | C18: טיפוס | H18: =VLOOKUP(H16,Check[],6,FALSE) -> 4801 | P18: =VLOOKUP(P16,Check[],6,FALSE) -> 4802 | Y18: =VLOOKUP(Y16,Check[],6,FALSE) -> 4801 | AO18: =VLOOKUP(AO16,Check[],6,FALSE) -> 4801 | AQ18: =VLOOKUP(AQ16,Check[],6,FALSE) -> 4802 | AY18: =VLOOKUP(AY16,Check[],6,FALSE) -> 4801 | BL18: טיפוס | BM18: =BM22+3.84 -> 175.48 | BP18: טיפוס
A19: 5 דירות בקומה | B19: =_xlfn.CONCAT("קומה ",B20) -> קומה 47 | C19: דירה | H19: =H23+5 -> 328 | O19: =O23+5 -> 329 | R19: =R23+5 -> 330 | V19: =V23+5 -> 331 | Y19: =Y23+5 -> 332 | AO19: =AO23+5 -> 326 | AQ19: =AQ23+5 -> 325 | AS19: =AS23+5 -> 324 | AW19: =AW23+5 -> 323 | BA19: =BA23+5 -> 322 | BL19: דירה | BM19: =_xlfn.CONCAT("קומה ",BM20) -> קומה 47 | BN19: 5 דירות בקומה | BP19: דירה
B20: =B24+1 -> 47 | C20: סטטוס | H20: =VLOOKUP("*"&H$5&".Ap."&H19,Check[],1,FALSE) -> O.P.4D.TS.Ap.328 | I20: =H20 -> O.P.4D.TS.Ap.328 | J20: =I20 -> O.P.4D.TS.Ap.328 | K20: =J20 -> O.P.4D.TS.Ap.328 | L20: =K20 -> O.P.4D.TS.Ap.328 | M20: =L20 -> O.P.4D.TS.Ap.328 | N20: =M20 -> O.P.4D.TS.Ap.328 | O20: =VLOOKUP("*"&O$5&".Ap."&O19,Check[],1,FALSE) -> O.P.4E.TS.Ap.329 | P20: =O20 -> O.P.4E.TS.Ap.329 | Q20: =P20 -> O.P.4E.TS.Ap.329 | R20: =VLOOKUP("*"&R$5&".Ap."&R19,Check[],1,FALSE) -> O.P.4F.TS.Ap.330 | S20: =R20 -> O.P.4F.TS.Ap.330 | T20: =S20 -> O.P.4F.TS.Ap.330 | U20: =T20 -> O.P.4F.TS.Ap.330 | V20: =VLOOKUP("*"&V$5&".Ap."&V19,Check[],1,FALSE) -> O.P.5AP.TS.Ap.331 | W20: =V20 -> O.P.5AP.TS.Ap.331 | X20: =V20 -> O.P.5AP.TS.Ap.331 | Y20: =VLOOKUP("*"&Y$5&".Ap."&Y19,Check[],1,FALSE) -> V.GMC.P.5BP.TS.Ap.332 | Z20: =Y20 -> V.GMC.P.5BP.TS.Ap.332 | AA20: =Y20 -> V.GMC.P.5BP.TS.Ap.332 | AO20: =VLOOKUP("*"&AO$5&".Ap."&AO19,Check[],1,FALSE) -> O.P.5BP.TN.Ap.326 | AP20: =AO20 -> O.P.5BP.TN.Ap.326 | AQ20: =VLOOKUP("*"&AQ$5&".Ap."&AQ19,Check[],1,FALSE) -> O.P.5AP.TN.Ap.325 | AR20: =AQ20 -> O.P.5AP.TN.Ap.325 | AS20: =VLOOKUP("*"&AS$5&".Ap."&AS19,Check[],1,FALSE) -> S.P.4F.TN.Ap.324 | AT20: =AS20 -> S.P.4F.TN.Ap.324 | AU20: =AT20 -> S.P.4F.TN.Ap.324 | AV20: =AU20 -> S.P.4F.TN.Ap.324 | AW20: =VLOOKUP("*"&AW$5&".Ap."&AW19,Check[],1,FALSE) -> O.P.4E.TN.Ap.323 | AX20: =AW20 -> O.P.4E.TN.Ap.323 | AY20: =AX20 -> O.P.4E.TN.Ap.323 | AZ20: =AY20 -> O.P.4E.TN.Ap.323 | BA20: =VLOOKUP("*"&BA$5&".Ap."&BA19,Check[],1,FALSE) -> V.GMS.P.4D.TN.Ap.322 | BB20: =BA20 -> V.GMS.P.4D.TN.Ap.322 | BC20: =BB20 -> V.GMS.P.4D.TN.Ap.322 | BD20: =BC20 -> V.GMS.P.4D.TN.Ap.322 | BE20: =BD20 -> V.GMS.P.4D.TN.Ap.322 | BF20: =BE20 -> V.GMS.P.4D.TN.Ap.322 | BG20: =BF20 -> V.GMS.P.4D.TN.Ap.322 | BL20: סטטוס | BM20: =BM24+1 -> 47 | BP20: סטטוס
C21: # צל | H21: =VLOOKUP(H20,Check[],5,FALSE) -> 328 | O21: =VLOOKUP(O20,Check[],5,FALSE) -> 329 | R21: =VLOOKUP(R20,Check[],5,FALSE) -> 330 | V21: =VLOOKUP(V20,Check[],5,FALSE) -> 331 | Y21: =VLOOKUP(Y20,Check[],5,FALSE) -> 332 | AN21: קוד | AO21: =VLOOKUP(AO20,Check[],5,FALSE) -> 326 | AQ21: =VLOOKUP(AQ20,Check[],5,FALSE) -> 325 | AS21: =VLOOKUP(AS20,Check[],5,FALSE) -> 324 | AW21: =VLOOKUP(AW20,Check[],5,FALSE) -> 323 | BA21: =VLOOKUP(BA20,Check[],5,FALSE) -> 322 | BL21: # צל | BP21: צל
B22: =B26+3.6 -> 171.64 | C22: טיפוס | H22: =VLOOKUP(H20,Check[],6,FALSE) -> 4701 | O22: =VLOOKUP(O20,Check[],6,FALSE) -> 4702 | R22: =VLOOKUP(R20,Check[],6,FALSE) -> 4703 | V22: =VLOOKUP(V20,Check[],6,FALSE) -> 4704 | Y22: =VLOOKUP(Y20,Check[],6,FALSE) -> 4705 | AN22: 121 | AO22: =VLOOKUP(AO20,Check[],6,FALSE) -> 4702 | AQ22: =VLOOKUP(AQ20,Check[],6,FALSE) -> 4703 | AS22: =VLOOKUP(AS20,Check[],6,FALSE) -> 4704 | AW22: =VLOOKUP(AW20,Check[],6,FALSE) -> 4705 | BA22: =VLOOKUP(BA20,Check[],6,FALSE) -> 4701 | BL22: טיפוס | BM22: =BM26+3.6 -> 171.64 | BP22: טיפוס
B23: =_xlfn.CONCAT("קומה ",B24) -> קומה 46 | C23: דירה | H23: =H27+5 -> 323 | O23: =O27+5 -> 324 | R23: =R27+5 -> 325 | V23: =V27+5 -> 326 | Y23: =Y27+5 -> 327 | AC23: מגדל דרומי | AH23: כל הפרויקט | AI23: מגדל צפוני | AN23: 122 | AO23: =AO27+5 -> 321 | AQ23: =AQ27+5 -> 320 | AS23: =AS27+5 -> 319 | AW23: =AW27+5 -> 318 | BA23: =BA27+5 -> 317 | BL23: דירה | BM23: =_xlfn.CONCAT("קומה ",BM24) -> קומה 46 | BP23: דירה
B24: =B28+1 -> 46 | C24: סטטוס | H24: =VLOOKUP("*"&H$5&".Ap."&H23,Check[],1,FALSE) -> O.P.4D.TS.Ap.323 | I24: =H24 -> O.P.4D.TS.Ap.323 | J24: =I24 -> O.P.4D.TS.Ap.323 | K24: =J24 -> O.P.4D.TS.Ap.323 | L24: =K24 -> O.P.4D.TS.Ap.323 | M24: =L24 -> O.P.4D.TS.Ap.323 | N24: =M24 -> O.P.4D.TS.Ap.323 | O24: =VLOOKUP("*"&O$5&".Ap."&O23,Check[],1,FALSE) -> O.P.4E.TS.Ap.324 | P24: =O24 -> O.P.4E.TS.Ap.324 | Q24: =P24 -> O.P.4E.TS.Ap.324 | R24: =VLOOKUP("*"&R$5&".Ap."&R23,Check[],1,FALSE) -> O.P.4F.TS.Ap.325 | S24: =R24 -> O.P.4F.TS.Ap.325 | T24: =S24 -> O.P.4F.TS.Ap.325 | U24: =T24 -> O.P.4F.TS.Ap.325 | V24: =VLOOKUP("*"&V$5&".Ap."&V23,Check[],1,FALSE) -> O.P.5AP.TS.Ap.326 | W24: =V24 -> O.P.5AP.TS.Ap.326 | X24: =V24 -> O.P.5AP.TS.Ap.326 | Y24: =VLOOKUP("*"&Y$5&".Ap."&Y23,Check[],1,FALSE) -> V.GMC.P.5BP.TS.Ap.327 | Z24: =Y24 -> V.GMC.P.5BP.TS.Ap.327 | AA24: =Y24 -> V.GMC.P.5BP.TS.Ap.327 | AO24: =VLOOKUP("*"&AO$5&".Ap."&AO23,Check[],1,FALSE) -> V.GMC.P.5BP.TN.Ap.321 | AP24: =AO24 -> V.GMC.P.5BP.TN.Ap.321 | AQ24: =VLOOKUP("*"&AQ$5&".Ap."&AQ23,Check[],1,FALSE) -> O.P.5AP.TN.Ap.320 | AR24: =AQ24 -> O.P.5AP.TN.Ap.320 | AS24: =VLOOKUP("*"&AS$5&".Ap."&AS23,Check[],1,FALSE) -> S.P.4F.TN.Ap.319 | AT24: =AS24 -> S.P.4F.TN.Ap.319 | AU24: =AT24 -> S.P.4F.TN.Ap.319 | AV24: =AU24 -> S.P.4F.TN.Ap.319 | AW24: =VLOOKUP("*"&AW$5&".Ap."&AW23,Check[],1,FALSE) -> O.P.4E.TN.Ap.318 | AX24: =AW24 -> O.P.4E.TN.Ap.318 | AY24: =AX24 -> O.P.4E.TN.Ap.318 | AZ24: =AY24 -> O.P.4E.TN.Ap.318 | BA24: =VLOOKUP("*"&BA$5&".Ap."&BA23,Check[],1,FALSE) -> V.DS.P.4D.TN.Ap.317 | BB24: =BA24 -> V.DS.P.4D.TN.Ap.317 | BC24: =BB24 -> V.DS.P.4D.TN.Ap.317 | BD24: =BC24 -> V.DS.P.4D.TN.Ap.317 | BE24: =BD24 -> V.DS.P.4D.TN.Ap.317 | BF24: =BE24 -> V.DS.P.4D.TN.Ap.317 | BG24: =BF24 -> V.DS.P.4D.TN.Ap.317 | BL24: סטטוס | BM24: =BM28+1 -> 46 | BP24: סטטוס
C25: # צל | H25: =VLOOKUP(H24,Check[],5,FALSE) -> 323 | O25: =VLOOKUP(O24,Check[],5,FALSE) -> 324 | R25: =VLOOKUP(R24,Check[],5,FALSE) -> 325 | V25: =VLOOKUP(V24,Check[],5,FALSE) -> 326 | Y25: =VLOOKUP(Y24,Check[],5,FALSE) -> 327 | AC25: טיפוס | AD25: פנויות | AE25: מכורות | AF25: בעלים | AG25: סה"כ | AI25: סה"כ | AJ25: בעלים | AK25: מכורות | AL25: פנויות | AM25: טיפוס | AN25: 123 | AO25: =VLOOKUP(AO24,Check[],5,FALSE) -> 321 | AQ25: =VLOOKUP(AQ24,Check[],5,FALSE) -> 320 | AS25: =VLOOKUP(AS24,Check[],5,FALSE) -> 319 | AW25: =VLOOKUP(AW24,Check[],5,FALSE) -> 318 | BA25: =VLOOKUP(BA24,Check[],5,FALSE) -> 317 | BL25: # צל | BP25: צל
B26: =B30+3.6 -> 168.04 | C26: טיפוס | H26: =VLOOKUP(H24,Check[],6,FALSE) -> 4601 | O26: =VLOOKUP(O24,Check[],6,FALSE) -> 4602 | R26: =VLOOKUP(R24,Check[],6,FALSE) -> 4603 | V26: =VLOOKUP(V24,Check[],6,FALSE) -> 4604 | Y26: =VLOOKUP(Y24,Check[],6,FALSE) -> 4605 | AN26: 124 | AO26: =VLOOKUP(AO24,Check[],6,FALSE) -> 4602 | AQ26: =VLOOKUP(AQ24,Check[],6,FALSE) -> 4603 | AS26: =VLOOKUP(AS24,Check[],6,FALSE) -> 4604 | AW26: =VLOOKUP(AW24,Check[],6,FALSE) -> 4605 | BA26: =VLOOKUP(BA24,Check[],6,FALSE) -> 4601 | BL26: טיפוס | BM26: =BM30+3.6 -> 168.04 | BP26: טיפוס
B27: =_xlfn.CONCAT("קומה ",B28) -> קומה 45 | C27: דירה | H27: =H31+5 -> 318 | O27: =O31+5 -> 319 | R27: =R31+5 -> 320 | V27: =V31+5 -> 321 | Y27: =Y31+5 -> 322 | AC27: 2A | AD27: =COUNTIF(Check[סימון],("V."&"*"&$AC27&"."&AD$5&"*")) -> 1 | AE27: =COUNTIF(Check[סימון],("S."&"*"&$AC27&"."&AE$5&"*")) -> 6 | AF27: =COUNTIF(Check[סימון],("O."&"*"&$AC27&"."&AF$5&"*")) -> 2 | AG27: =SUM(AD27:AF27) -> 9 | AH27: =SUM(AI27,AG27) -> 17 | AI27: =SUM(AJ27:AL27) -> 8 | AJ27: =COUNTIF(Check[סימון],("O."&"*"&$AC27&"."&AJ$5&"*")) -> 3 | AK27: =COUNTIF(Check[סימון],("S."&"*"&$AC27&"."&AK$5&"*")) -> 5 | AL27: =COUNTIF(Check[סימון],("V."&"*"&$AC27&"."&AL$5&"*")) -> 0 | AM27: 2A | AO27: =AO31+5 -> 316 | AQ27: =AQ31+5 -> 315 | AS27: =AS31+5 -> 314 | AW27: =AW31+5 -> 313 | BA27: =BA31+5 -> 312 | BL27: דירה | BM27: =_xlfn.CONCAT("קומה ",BM28) -> קומה 45 | BP27: דירה
B28: =B32+1 -> 45 | C28: סטטוס | H28: =VLOOKUP("*"&H$5&".Ap."&H27,Check[],1,FALSE) -> O.P.4D.TS.Ap.318 | I28: =H28 -> O.P.4D.TS.Ap.318 | J28: =I28 -> O.P.4D.TS.Ap.318 | K28: =J28 -> O.P.4D.TS.Ap.318 | L28: =K28 -> O.P.4D.TS.Ap.318 | M28: =L28 -> O.P.4D.TS.Ap.318 | N28: =M28 -> O.P.4D.TS.Ap.318 | O28: =VLOOKUP("*"&O$5&".Ap."&O27,Check[],1,FALSE) -> S.P.4E.TS.Ap.319 | P28: =O28 -> S.P.4E.TS.Ap.319 | Q28: =P28 -> S.P.4E.TS.Ap.319 | R28: =VLOOKUP("*"&R$5&".Ap."&R27,Check[],1,FALSE) -> O.P.4F.TS.Ap.320 | S28: =R28 -> O.P.4F.TS.Ap.320 | T28: =S28 -> O.P.4F.TS.Ap.320 | U28: =T28 -> O.P.4F.TS.Ap.320 | V28: =VLOOKUP("*"&V$5&".Ap."&V27,Check[],1,FALSE) -> O.P.5AP.TS.Ap.321 | W28: =V28 -> O.P.5AP.TS.Ap.321 | X28: =V28 -> O.P.5AP.TS.Ap.321 | Y28: =VLOOKUP("*"&Y$5&".Ap."&Y27,Check[],1,FALSE) -> V.GMC.P.5BP.TS.Ap.322 | Z28: =Y28 -> V.GMC.P.5BP.TS.Ap.322 | AA28: =Y28 -> V.GMC.P.5BP.TS.Ap.322 | AO28: =VLOOKUP("*"&AO$5&".Ap."&AO27,Check[],1,FALSE) -> V.GMC.P.5BP.TN.Ap.316 | AP28: =AO28 -> V.GMC.P.5BP.TN.Ap.316 | AQ28: =VLOOKUP("*"&AQ$5&".Ap."&AQ27,Check[],1,FALSE) -> O.P.5AP.TN.Ap.315 | AR28: =AQ28 -> O.P.5AP.TN.Ap.315 | AS28: =VLOOKUP("*"&AS$5&".Ap."&AS27,Check[],1,FALSE) -> S.P.4F.TN.Ap.314 | AT28: =AS28 -> S.P.4F.TN.Ap.314 | AU28: =AT28 -> S.P.4F.TN.Ap.314 | AV28: =AU28 -> S.P.4F.TN.Ap.314 | AW28: =VLOOKUP("*"&AW$5&".Ap."&AW27,Check[],1,FALSE) -> S.P.4E.TN.Ap.313 | AX28: =AW28 -> S.P.4E.TN.Ap.313 | AY28: =AX28 -> S.P.4E.TN.Ap.313 | AZ28: =AY28 -> S.P.4E.TN.Ap.313 | BA28: =VLOOKUP("*"&BA$5&".Ap."&BA27,Check[],1,FALSE) -> O.P.4D.TN.Ap.312 | BB28: =BA28 -> O.P.4D.TN.Ap.312 | BC28: =BB28 -> O.P.4D.TN.Ap.312 | BD28: =BC28 -> O.P.4D.TN.Ap.312 | BE28: =BD28 -> O.P.4D.TN.Ap.312 | BF28: =BE28 -> O.P.4D.TN.Ap.312 | BG28: =BF28 -> O.P.4D.TN.Ap.312 | BL28: סטטוס | BM28: =BM32+1 -> 45 | BP28: סטטוס
C29: # צל | H29: =VLOOKUP(H28,Check[],5,FALSE) -> 318 | O29: =VLOOKUP(O28,Check[],5,FALSE) -> 319 | R29: =VLOOKUP(R28,Check[],5,FALSE) -> 320 | V29: =VLOOKUP(V28,Check[],5,FALSE) -> 321 | Y29: =VLOOKUP(Y28,Check[],5,FALSE) -> 322 | AC29: 2B | AD29: =COUNTIF(Check[סימון],("V."&"*"&$AC29&"."&AD$5&"*")) -> 0 | AE29: =COUNTIF(Check[סימון],("S."&"*"&$AC29&"."&AE$5&"*")) -> 5 | AF29: =COUNTIF(Check[סימון],("O."&"*"&$AC29&"."&AF$5&"*")) -> 4 | AG29: =SUM(AD29:AF29) -> 9 | AH29: =SUM(AI29,AG29) -> 17 | AI29: =SUM(AJ29:AL29) -> 8 | AJ29: =COUNTIF(Check[סימון],("O."&"*"&$AC29&"."&AJ$5&"*")) -> 1 | AK29: =COUNTIF(Check[סימון],("S."&"*"&$AC29&"."&AK$5&"*")) -> 7 | AL29: =COUNTIF(Check[סימון],("V."&"*"&$AC29&"."&AL$5&"*")) -> 0 | AM29: 3E | AO29: =VLOOKUP(AO28,Check[],5,FALSE) -> 316 | AQ29: =VLOOKUP(AQ28,Check[],5,FALSE) -> 315 | AS29: =VLOOKUP(AS28,Check[],5,FALSE) -> 314 | AW29: =VLOOKUP(AW28,Check[],5,FALSE) -> 313 | BA29: =VLOOKUP(BA28,Check[],5,FALSE) -> 312 | BL29: # צל | BP29: צל
B30: =B34+3.6 -> 164.44 | C30: טיפוס | H30: =VLOOKUP(H28,Check[],6,FALSE) -> 4501 | O30: =VLOOKUP(O28,Check[],6,FALSE) -> 4502 | R30: =VLOOKUP(R28,Check[],6,FALSE) -> 4503 | V30: =VLOOKUP(V28,Check[],6,FALSE) -> 4504 | Y30: =VLOOKUP(Y28,Check[],6,FALSE) -> 4505 | AO30: =VLOOKUP(AO28,Check[],6,FALSE) -> 4502 | AQ30: =VLOOKUP(AQ28,Check[],6,FALSE) -> 4503 | AS30: =VLOOKUP(AS28,Check[],6,FALSE) -> 4504 | AW30: =VLOOKUP(AW28,Check[],6,FALSE) -> 4505 | BA30: =VLOOKUP(BA28,Check[],6,FALSE) -> 4501 | BL30: טיפוס | BM30: =BM34+3.6 -> 164.44 | BP30: טיפוס
B31: =_xlfn.CONCAT("קומה ",B32) -> קומה 44 | C31: דירה | H31: =H35+5 -> 313 | O31: =O35+5 -> 314 | R31: =R35+5 -> 315 | V31: =V35+5 -> 316 | Y31: =Y35+5 -> 317 | AC31: 2C | AD31: =COUNTIF(Check[סימון],("V."&"*"&$AC31&"."&AD$5&"*")) -> 0 | AE31: =COUNTIF(Check[סימון],("S."&"*"&$AC31&"."&AE$5&"*")) -> 5 | AF31: =COUNTIF(Check[סימון],("O."&"*"&$AC31&"."&AF$5&"*")) -> 5 | AG31: =SUM(AD31:AF31) -> 10 | AH31: =SUM(AI31,AG31) -> 18 | AI31: =SUM(AJ31:AL31) -> 8 | AJ31: =COUNTIF(Check[סימון],("O."&"*"&$AC31&"."&AJ$5&"*")) -> 2 | AK31: =COUNTIF(Check[סימון],("S."&"*"&$AC31&"."&AK$5&"*")) -> 6 | AL31: =COUNTIF(Check[סימון],("V."&"*"&$AC31&"."&AL$5&"*")) -> 0 | AM31: 2C | AO31: =AO35+5 -> 311 | AQ31: =AQ35+5 -> 310 | AS31: =AS35+5 -> 309 | AW31: =AW35+5 -> 308 | BA31: =BA35+5 -> 307 | BL31: דירה | BM31: =_xlfn.CONCAT("קומה ",BM32) -> קומה 44 | BP31: דירה
B32: =B36+1 -> 44 | C32: סטטוס | H32: =VLOOKUP("*"&H$5&".Ap."&H31,Check[],1,FALSE) -> S.P.4D.TS.Ap.313 | I32: =H32 -> S.P.4D.TS.Ap.313 | J32: =I32 -> S.P.4D.TS.Ap.313 | K32: =J32 -> S.P.4D.TS.Ap.313 | L32: =K32 -> S.P.4D.TS.Ap.313 | M32: =L32 -> S.P.4D.TS.Ap.313 | N32: =M32 -> S.P.4D.TS.Ap.313 | O32: =VLOOKUP("*"&O$5&".Ap."&O31,Check[],1,FALSE) -> S.P.4E.TS.Ap.314 | P32: =O32 -> S.P.4E.TS.Ap.314 | Q32: =P32 -> S.P.4E.TS.Ap.314 | R32: =VLOOKUP("*"&R$5&".Ap."&R31,Check[],1,FALSE) -> O.P.4F.TS.Ap.315 | S32: =R32 -> O.P.4F.TS.Ap.315 | T32: =S32 -> O.P.4F.TS.Ap.315 | U32: =T32 -> O.P.4F.TS.Ap.315 | V32: =VLOOKUP("*"&V$5&".Ap."&V31,Check[],1,FALSE) -> O.P.5AP.TS.Ap.316 | W32: =V32 -> O.P.5AP.TS.Ap.316 | X32: =V32 -> O.P.5AP.TS.Ap.316 | Y32: =VLOOKUP("*"&Y$5&".Ap."&Y31,Check[],1,FALSE) -> O.P.5BP.TS.Ap.317 | Z32: =Y32 -> O.P.5BP.TS.Ap.317 | AA32: =Y32 -> O.P.5BP.TS.Ap.317 | AO32: =VLOOKUP("*"&AO$5&".Ap."&AO31,Check[],1,FALSE) -> V.GMC.P.5BP.TN.Ap.311 | AP32: =AO32 -> V.GMC.P.5BP.TN.Ap.311 | AQ32: =VLOOKUP("*"&AQ$5&".Ap."&AQ31,Check[],1,FALSE) -> O.P.5AP.TN.Ap.310 | AR32: =AQ32 -> O.P.5AP.TN.Ap.310 | AS32: =VLOOKUP("*"&AS$5&".Ap."&AS31,Check[],1,FALSE) -> S.P.4F.TN.Ap.309 | AT32: =AS32 -> S.P.4F.TN.Ap.309 | AU32: =AT32 -> S.P.4F.TN.Ap.309 | AV32: =AU32 -> S.P.4F.TN.Ap.309 | AW32: =VLOOKUP("*"&AW$5&".Ap."&AW31,Check[],1,FALSE) -> S.P.4E.TN.Ap.308 | AX32: =AW32 -> S.P.4E.TN.Ap.308 | AY32: =AX32 -> S.P.4E.TN.Ap.308 | AZ32: =AY32 -> S.P.4E.TN.Ap.308 | BA32: =VLOOKUP("*"&BA$5&".Ap."&BA31,Check[],1,FALSE) -> O.P.4D.TN.Ap.307 | BB32: =BA32 -> O.P.4D.TN.Ap.307 | BC32: =BB32 -> O.P.4D.TN.Ap.307 | BD32: =BC32 -> O.P.4D.TN.Ap.307 | BE32: =BD32 -> O.P.4D.TN.Ap.307 | BF32: =BE32 -> O.P.4D.TN.Ap.307 | BG32: =BF32 -> O.P.4D.TN.Ap.307 | BL32: סטטוס | BM32: =BM36+1 -> 44 | BP32: סטטוס
C33: # צל | H33: =VLOOKUP(H32,Check[],5,FALSE) -> 313 | O33: =VLOOKUP(O32,Check[],5,FALSE) -> 314 | R33: =VLOOKUP(R32,Check[],5,FALSE) -> 315 | V33: =VLOOKUP(V32,Check[],5,FALSE) -> 316 | Y33: =VLOOKUP(Y32,Check[],5,FALSE) -> 317 | AC33: 2D | AD33: =COUNTIF(Check[סימון],("V."&"*"&$AC33&"."&AD$5&"*")) -> 1 | AE33: =COUNTIF(Check[סימון],("S."&"*"&$AC33&"."&AE$5&"*")) -> 14 | AF33: =COUNTIF(Check[סימון],("O."&"*"&$AC33&"."&AF$5&"*")) -> 6 | AG33: =SUM(AD33:AF33) -> 21 | AH33: =SUM(AI33,AG33) -> 42 | AI33: =SUM(AJ33:AL33) -> 21 | AJ33: =COUNTIF(Check[סימון],("O."&"*"&$AC33&"."&AJ$5&"*")) -> 0 | AK33: =COUNTIF(Check[סימון],("S."&"*"&$AC33&"."&AK$5&"*")) -> 16 | AL33: =COUNTIF(Check[סימון],("V."&"*"&$AC33&"."&AL$5&"*")) -> 5 | AM33: 3E | AO33: =VLOOKUP(AO32,Check[],5,FALSE) -> 311 | AQ33: =VLOOKUP(AQ32,Check[],5,FALSE) -> 310 | AS33: =VLOOKUP(AS32,Check[],5,FALSE) -> 309 | AW33: =VLOOKUP(AW32,Check[],5,FALSE) -> 308 | BA33: =VLOOKUP(BA32,Check[],5,FALSE) -> 307 | BL33: # צל | BP33: צל
B34: =B38+3.6 -> 160.84 | C34: טיפוס | H34: =VLOOKUP(H32,Check[],6,FALSE) -> 4401 | O34: =VLOOKUP(O32,Check[],6,FALSE) -> 4402 | R34: =VLOOKUP(R32,Check[],6,FALSE) -> 4403 | V34: =VLOOKUP(V32,Check[],6,FALSE) -> 4404 | Y34: =VLOOKUP(Y32,Check[],6,FALSE) -> 4405 | AO34: =VLOOKUP(AO32,Check[],6,FALSE) -> 4402 | AQ34: =VLOOKUP(AQ32,Check[],6,FALSE) -> 4403 | AS34: =VLOOKUP(AS32,Check[],6,FALSE) -> 4404 | AW34: =VLOOKUP(AW32,Check[],6,FALSE) -> 4405 | BA34: =VLOOKUP(BA32,Check[],6,FALSE) -> 4401 | BL34: טיפוס | BM34: =BM38+3.6 -> 160.84 | BP34: טיפוס
B35: =_xlfn.CONCAT("קומה ",B36) -> קומה 43 | C35: דירה | H35: =H39+5 -> 308 | O35: =O39+5 -> 309 | R35: =R39+5 -> 310 | V35: =V39+5 -> 311 | Y35: =Y39+5 -> 312 | AC35: 2E | AD35: =COUNTIF(Check[סימון],("V."&"*"&$AC35&"."&AD$5&"*")) -> 3 | AE35: =COUNTIF(Check[סימון],("S."&"*"&$AC35&"."&AE$5&"*")) -> 5 | AF35: =COUNTIF(Check[סימון],("O."&"*"&$AC35&"."&AF$5&"*")) -> 1 | AG35: =SUM(AD35:AF35) -> 9 | AH35: =SUM(AI35,AG35) -> 16 | AI35: =SUM(AJ35:AL35) -> 7 | AJ35: =COUNTIF(Check[סימון],("O."&"*"&$AC35&"."&AJ$5&"*")) -> 0 | AK35: =COUNTIF(Check[סימון],("S."&"*"&$AC35&"."&AK$5&"*")) -> 7 | AL35: =COUNTIF(Check[סימון],("V."&"*"&$AC35&"."&AL$5&"*")) -> 0 | AM35: 2E | AO35: =AO39+5 -> 306 | AQ35: =AQ39+5 -> 305 | AS35: =AS39+5 -> 304 | AW35: =AW39+5 -> 303 | BA35: =BA39+5 -> 302 | BL35: דירה | BM35: =_xlfn.CONCAT("קומה ",BM36) -> קומה 43 | BP35: דירה
B36: =B40+1 -> 43 | C36: סטטוס | H36: =VLOOKUP("*"&H$5&".Ap."&H35,Check[],1,FALSE) -> V.GMS.P.4D.TS.Ap.308 | I36: =H36 -> V.GMS.P.4D.TS.Ap.308 | J36: =I36 -> V.GMS.P.4D.TS.Ap.308 | K36: =J36 -> V.GMS.P.4D.TS.Ap.308 | L36: =K36 -> V.GMS.P.4D.TS.Ap.308 | M36: =L36 -> V.GMS.P.4D.TS.Ap.308 | N36: =M36 -> V.GMS.P.4D.TS.Ap.308 | O36: =VLOOKUP("*"&O$5&".Ap."&O35,Check[],1,FALSE) -> O.P.4E.TS.Ap.309 | P36: =O36 -> O.P.4E.TS.Ap.309 | Q36: =P36 -> O.P.4E.TS.Ap.309 | R36: =VLOOKUP("*"&R$5&".Ap."&R35,Check[],1,FALSE) -> O.P.4F.TS.Ap.310 | S36: =R36 -> O.P.4F.TS.Ap.310 | T36: =S36 -> O.P.4F.TS.Ap.310 | U36: =T36 -> O.P.4F.TS.Ap.310 | V36: =VLOOKUP("*"&V$5&".Ap."&V35,Check[],1,FALSE) -> S.P.5CP.TS.Ap.311 | W36: =V36 -> S.P.5CP.TS.Ap.311 | X36: =V36 -> S.P.5CP.TS.Ap.311 | Y36: =VLOOKUP("*"&Y$5&".Ap."&Y35,Check[],1,FALSE) -> S.P.4BP.TS.Ap.312 | Z36: =Y36 -> S.P.4BP.TS.Ap.312 | AA36: =Y36 -> S.P.4BP.TS.Ap.312 | AO36: =VLOOKUP("*"&AO$5&".Ap."&AO35,Check[],1,FALSE) -> S.P.5BP.TN.Ap.306 | AP36: =AO36 -> S.P.5BP.TN.Ap.306 | AQ36: =VLOOKUP("*"&AQ$5&".Ap."&AQ35,Check[],1,FALSE) -> S.P.5AP.TN.Ap.305 | AR36: =AQ36 -> S.P.5AP.TN.Ap.305 | AS36: =VLOOKUP("*"&AS$5&".Ap."&AS35,Check[],1,FALSE) -> O.P.4F.TN.Ap.304 | AT36: =AS36 -> O.P.4F.TN.Ap.304 | AU36: =AT36 -> O.P.4F.TN.Ap.304 | AV36: =AU36 -> O.P.4F.TN.Ap.304 | AW36: =VLOOKUP("*"&AW$5&".Ap."&AW35,Check[],1,FALSE) -> O.P.4E.TN.Ap.303 | AX36: =AW36 -> O.P.4E.TN.Ap.303 | AY36: =AX36 -> O.P.4E.TN.Ap.303 | AZ36: =AY36 -> O.P.4E.TN.Ap.303 | BA36: =VLOOKUP("*"&BA$5&".Ap."&BA35,Check[],1,FALSE) -> V.GMS.P.4D.TN.Ap.302 | BB36: =BA36 -> V.GMS.P.4D.TN.Ap.302 | BC36: =BB36 -> V.GMS.P.4D.TN.Ap.302 | BD36: =BC36 -> V.GMS.P.4D.TN.Ap.302 | BE36: =BD36 -> V.GMS.P.4D.TN.Ap.302 | BF36: =BE36 -> V.GMS.P.4D.TN.Ap.302 | BG36: =BF36 -> V.GMS.P.4D.TN.Ap.302 | BL36: סטטוס | BM36: =BM40+1 -> 43 | BP36: סטטוס
C37: # צל | H37: =VLOOKUP(H36,Check[],5,FALSE) -> 308 | O37: =VLOOKUP(O36,Check[],5,FALSE) -> 309 | R37: =VLOOKUP(R36,Check[],5,FALSE) -> 310 | V37: =VLOOKUP(V36,Check[],5,FALSE) -> 311 | Y37: =VLOOKUP(Y36,Check[],5,FALSE) -> 312 | AC37: 2F | AD37: =COUNTIF(Check[סימון],("V."&"*"&$AC37&"."&AD$5&"*")) -> 1 | AE37: =COUNTIF(Check[סימון],("S."&"*"&$AC37&"."&AE$5&"*")) -> 2 | AF37: =COUNTIF(Check[סימון],("O."&"*"&$AC37&"."&AF$5&"*")) -> 6 | AG37: =SUM(AD37:AF37) -> 9 | AH37: =SUM(AI37,AG37) -> 16 | AI37: =SUM(AJ37:AL37) -> 7 | AJ37: =COUNTIF(Check[סימון],("O."&"*"&$AC37&"."&AJ$5&"*")) -> 4 | AK37: =COUNTIF(Check[סימון],("S."&"*"&$AC37&"."&AK$5&"*")) -> 3 | AL37: =COUNTIF(Check[סימון],("V."&"*"&$AC37&"."&AL$5&"*")) -> 0 | AM37: 3E | AO37: =VLOOKUP(AO36,Check[],5,FALSE) -> 306 | AQ37: =VLOOKUP(AQ36,Check[],5,FALSE) -> 305 | AS37: =VLOOKUP(AS36,Check[],5,FALSE) -> 304 | AW37: =VLOOKUP(AW36,Check[],5,FALSE) -> 303 | BA37: =VLOOKUP(BA36,Check[],5,FALSE) -> 302 | BL37: # צל | BP37: צל
B38: =B42+3.6 -> 157.24 | C38: טיפוס | H38: =VLOOKUP(H36,Check[],6,FALSE) -> 4301 | O38: =VLOOKUP(O36,Check[],6,FALSE) -> 4302 | R38: =VLOOKUP(R36,Check[],6,FALSE) -> 4303 | V38: =VLOOKUP(V36,Check[],6,FALSE) -> 4304 | Y38: =VLOOKUP(Y36,Check[],6,FALSE) -> 4305 | AO38: =VLOOKUP(AO36,Check[],6,FALSE) -> 4302 | AQ38: =VLOOKUP(AQ36,Check[],6,FALSE) -> 4303 | AS38: =VLOOKUP(AS36,Check[],6,FALSE) -> 4304 | AW38: =VLOOKUP(AW36,Check[],6,FALSE) -> 4305 | BA38: =VLOOKUP(BA36,Check[],6,FALSE) -> 4301 | BL38: טיפוס | BM38: =BM42+3.6 -> 157.24 | BP38: טיפוס
B39: =_xlfn.CONCAT("קומה ",B40) -> קומה 42 | C39: דירה | H39: =H43+5 -> 303 | O39: =O43+5 -> 304 | R39: =R43+5 -> 305 | V39: =V43+5 -> 306 | Y39: =Y43+5 -> 307 | AC39: 2G | AD39: =COUNTIF(Check[סימון],("V."&"*"&$AC39&"."&AD$5&"*")) -> 9 | AE39: =COUNTIF(Check[סימון],("S."&"*"&$AC39&"."&AE$5&"*")) -> 5 | AF39: =COUNTIF(Check[סימון],("O."&"*"&$AC39&"."&AF$5&"*")) -> 5 | AG39: =SUM(AD39:AF39) -> 19 | AH39: =SUM(AI39,AG39) -> 37 | AI39: =SUM(AJ39:AL39) -> 18 | AJ39: =COUNTIF(Check[סימון],("O."&"*"&$AC39&"."&AJ$5&"*")) -> 4 | AK39: =COUNTIF(Check[סימון],("S."&"*"&$AC39&"."&AK$5&"*")) -> 14 | AL39: =COUNTIF(Check[סימון],("V."&"*"&$AC39&"."&AL$5&"*")) -> 0 | AM39: 2G | AO39: =AO43+5 -> 301 | AQ39: =AQ43+5 -> 300 | AS39: =AS43+5 -> 299 | AW39: =AW43+5 -> 298 | BA39: =BA43+5 -> 297 | BL39: דירה | BM39: =_xlfn.CONCAT("קומה ",BM40) -> קומה 42 | BP39: דירה
B40: =B44+1 -> 42 | C40: סטטוס | H40: =VLOOKUP("*"&H$5&".Ap."&H39,Check[],1,FALSE) -> V.GMS.P.4D.TS.Ap.303 | I40: =H40 -> V.GMS.P.4D.TS.Ap.303 | J40: =I40 -> V.GMS.P.4D.TS.Ap.303 | K40: =J40 -> V.GMS.P.4D.TS.Ap.303 | L40: =K40 -> V.GMS.P.4D.TS.Ap.303 | M40: =L40 -> V.GMS.P.4D.TS.Ap.303 | N40: =M40 -> V.GMS.P.4D.TS.Ap.303 | O40: =VLOOKUP("*"&O$5&".Ap."&O39,Check[],1,FALSE) -> O.P.4E.TS.Ap.304 | P40: =O40 -> O.P.4E.TS.Ap.304 | Q40: =P40 -> O.P.4E.TS.Ap.304 | R40: =VLOOKUP("*"&R$5&".Ap."&R39,Check[],1,FALSE) -> O.P.4F.TS.Ap.305 | S40: =R40 -> O.P.4F.TS.Ap.305 | T40: =S40 -> O.P.4F.TS.Ap.305 | U40: =T40 -> O.P.4F.TS.Ap.305 | V40: =VLOOKUP("*"&V$5&".Ap."&V39,Check[],1,FALSE) -> S.P.5CP.TS.Ap.306 | W40: =V40 -> S.P.5CP.TS.Ap.306 | X40: =V40 -> S.P.5CP.TS.Ap.306 | Y40: =VLOOKUP("*"&Y$5&".Ap."&Y39,Check[],1,FALSE) -> V.GM.P.4BP.TS.Ap.307 | Z40: =Y40 -> V.GM.P.4BP.TS.Ap.307 | AA40: =Y40 -> V.GM.P.4BP.TS.Ap.307 | AO40: =VLOOKUP("*"&AO$5&".Ap."&AO39,Check[],1,FALSE) -> V.GMC.P.5BP.TN.Ap.301 | AP40: =AO40 -> V.GMC.P.5BP.TN.Ap.301 | AQ40: =VLOOKUP("*"&AQ$5&".Ap."&AQ39,Check[],1,FALSE) -> O.P.5AP.TN.Ap.300 | AR40: =AQ40 -> O.P.5AP.TN.Ap.300 | AS40: =VLOOKUP("*"&AS$5&".Ap."&AS39,Check[],1,FALSE) -> O.P.4F.TN.Ap.299 | AT40: =AS40 -> O.P.4F.TN.Ap.299 | AU40: =AT40 -> O.P.4F.TN.Ap.299 | AV40: =AU40 -> O.P.4F.TN.Ap.299 | AW40: =VLOOKUP("*"&AW$5&".Ap."&AW39,Check[],1,FALSE) -> S.P.4E.TN.Ap.298 | AX40: =AW40 -> S.P.4E.TN.Ap.298 | AY40: =AX40 -> S.P.4E.TN.Ap.298 | AZ40: =AY40 -> S.P.4E.TN.Ap.298 | BA40: =VLOOKUP("*"&BA$5&".Ap."&BA39,Check[],1,FALSE) -> V.GMS.P.4D.TN.Ap.297 | BB40: =BA40 -> V.GMS.P.4D.TN.Ap.297 | BC40: =BB40 -> V.GMS.P.4D.TN.Ap.297 | BD40: =BC40 -> V.GMS.P.4D.TN.Ap.297 | BE40: =BD40 -> V.GMS.P.4D.TN.Ap.297 | BF40: =BE40 -> V.GMS.P.4D.TN.Ap.297 | BG40: =BF40 -> V.GMS.P.4D.TN.Ap.297 | BL40: סטטוס | BM40: =BM44+1 -> 42 | BP40: סטטוס
...

Sheet טבלת סטטוס
A2: סימון | B2: סימון2 | C2: מגדל | D2: קומה | E2: מספר דירה | F2: מספר צל | G2: טיפוס | H2: מספר חדרים | I2: סוג | J2: סוג מרפסת | K2: סטטוס | L2: סטטוס2 | M2: סטטוס מסירה | N2: סטטוס גמר | O2: הערות טבלה אלון | P2: סטטוס ביצוע-תוכניות +בחירות גמר | Q2: עדכון ע"פ מייל ליאור מיום 02/06/2026 (14/06/2026) | R2: ספק ריצופים וכלים סניטרים | S2: תאריך חתימה | T2: שם רוכש/בעלים | U2: שיוך חניה 1 | V2: שיוך חניה 2 | W2: שיוך מחסן | Y2: מקרא לגמר דירות ע"פ PDF 31/03/2026
A3: =_xlfn.CONCAT(VLOOKUP(Check[[#This Row],[סטטוס]],Sold,2,FALSE),IF(Check[[#This Row],[סטטוס]]="פנויה",IF(N3="גמר מלא סטנדרט",".GMS",IF(N3="גמר מלא טיוב חומרים",".GMC",IF(N3="גמר מינימלי",".GM",IF(N3="דירת שיווק",".DS","")))),""),".",VLOOKUP(Check[[#This Row],[טיפוס]],Tipus[],5,FALSE),".",VLOOKUP(Check[[#This Row],[מגדל]],Tower,2,FALSE),".Ap.",Check[[#This Row],[מספר דירה]]) -> O.S.2C.TS.Ap.1 | B3: =_xlfn.CONCAT(VLOOKUP(Check[[#This Row],[סטטוס]],Sold,2,FALSE),IF(Check[[#This Row],[סטטוס]]="פנויה",IF(N3="גמר מלא סטנדרט",".GMS",IF(N3="גמר מלא טיוב חומרים",".GMC",IF(N3="גמר מינימלי",".GM",IF(N3="דירת שיווק",".DS","")))),""),IF(M3="זומן לטרום",".ZLT",IF(M3="טרום מסירה",".TM",IF(M3="טרום מסירה מהנדס",".TMM",IF(M3="מסירת חזקה",".MH",IF(M3="מסירת חזקה מהנדס",".MHM",""))))),".",VLOOKUP(Check[[#This Row],[טיפוס]],Tipus[],5,FALSE),".",VLOOKUP(Check[[#This Row],[מגדל]],Tower,2,FALSE),".Ap.",Check[[#This Row],[מספר דירה]]) -> O.MH.S.2C.TS.Ap.1 | C3: דרומי | D3: 1 | E3: 1 | F3: 101 | G3: 2C* | H3: =VLOOKUP(Check[[#This Row],[טיפוס]],Tipus[],2,FALSE) -> 2 | I3: =VLOOKUP(Check[[#This Row],[טיפוס]],Tipus[],3,FALSE) -> סטנדרט | J3: =VLOOKUP(Check[[#This Row],[טיפוס]],Tipus[],4,FALSE) -> E | K3: =IF(Check[[#This Row],[סטטוס2]]="הולד","פנויה",Check[[#This Row],[סטטוס2]]) -> בעלים | L3: בעלים | M3: מסירת חזקה | S3: 44040 | T3: ישפה נדל"ן בע"מ | W3: 3-12 | Y3: גמר מינימלי
A4: =_xlfn.CONCAT(VLOOKUP(Check[[#This Row],[סטטוס]],Sold,2,FALSE),IF(Check[[#This Row],[סטטוס]]="פנויה",IF(N4="גמר מלא סטנדרט",".GMS",IF(N4="גמר מלא טיוב חומרים",".GMC",IF(N4="גמר מינימלי",".GM",IF(N4="דירת שיווק",".DS","")))),""),".",VLOOKUP(Check[[#This Row],[טיפוס]],Tipus[],5,FALSE),".",VLOOKUP(Check[[#This Row],[מגדל]],Tower,2,FALSE),".Ap.",Check[[#This Row],[מספר דירה]]) -> O.S.4G.TS.Ap.2 | B4: =_xlfn.CONCAT(VLOOKUP(Check[[#This Row],[סטטוס]],Sold,2,FALSE),IF(Check[[#This Row],[סטטוס]]="פנויה",IF(N4="גמר מלא סטנדרט",".GMS",IF(N4="גמר מלא טיוב חומרים",".GMC",IF(N4="גמר מינימלי",".GM",IF(N4="דירת שיווק",".DS","")))),""),IF(M4="זומן לטרום",".ZLT",IF(M4="טרום מסירה",".TM",IF(M4="טרום מסירה מהנדס",".TMM",IF(M4="מסירת חזקה",".MH",IF(M4="מסירת חזקה מהנדס",".MHM",""))))),".",VLOOKUP(Check[[#This Row],[טיפוס]],Tipus[],5,FALSE),".",VLOOKUP(Check[[#This Row],[מגדל]],Tower,2,FALSE),".Ap.",Check[[#This Row],[מספר דירה]]) -> O.S.4G.TS.Ap.2 | C4: דרומי | D4: 1 | E4: 2 | F4: 102 | G4: 4G | H4: =VLOOKUP(Check[[#This Row],[טיפוס]],Tipus[],2,FALSE) -> 4 | I4: =VLOOKUP(Check[[#This Row],[טיפוס]],Tipus[],3,FALSE) -> סטנדרט | J4: =VLOOKUP(Check[[#This Row],[טיפוס]],Tipus[],4,FALSE) -> 4G | K4: =IF(Check[[#This Row],[סטטוס2]]="הולד","פנויה",Check[[#This Row],[סטטוס2]]) -> בעלים | L4: בעלים | S4: 44040 | T4: אביעד שוב | U4: 5064 | V4: 5064A | Y4: גמר מלא סטנדרט
A5: =_xlfn.CONCAT(VLOOKUP(Check[[#This Row],[סטטוס]],Sold,2,FALSE),IF(Check[[#This Row],[סטטוס]]="פנויה",IF(N5="גמר מלא סטנדרט",".GMS",IF(N5="גמר מלא טיוב חומרים",".GMC",IF(N5="גמר מינימלי",".GM",IF(N5="דירת שיווק",".DS","")))),""),".",VLOOKUP(Check[[#This Row],[טיפוס]],Tipus[],5,FALSE),".",VLOOKUP(Check[[#This Row],[מגדל]],Tower,2,FALSE),".Ap.",Check[[#This Row],[מספר דירה]]) -> O.S.4H.TS.Ap.3 | B5: =_xlfn.CONCAT(VLOOKUP(Check[[#This Row],[סטטוס]],Sold,2,FALSE),IF(Check[[#This Row],[סטטוס]]="פנויה",IF(N5="גמר מלא סטנדרט",".GMS",IF(N5="גמר מלא טיוב חומרים",".GMC",IF(N5="גמר מינימלי",".GM",IF(N5="דירת שיווק",".DS","")))),""),IF(M5="זומן לטרום",".ZLT",IF(M5="טרום מסירה",".TM",IF(M5="טרום מסירה מהנדס",".TMM",IF(M5="מסירת חזקה",".MH",IF(M5="מסירת חזקה מהנדס",".MHM",""))))),".",VLOOKUP(Check[[#This Row],[טיפוס]],Tipus[],5,FALSE),".",VLOOKUP(Check[[#This Row],[מגדל]],Tower,2,FALSE),".Ap.",Check[[#This Row],[מספר דירה]]) -> O.S.4H.TS.Ap.3 | C5: דרומי | D5: 1 | E5: 3 | F5: 103 | G5: 4H | H5: =VLOOKUP(Check[[#This Row],[טיפוס]],Tipus[],2,FALSE) -> 4 | I5: =VLOOKUP(Check[[#This Row],[טיפוס]],Tipus[],3,FALSE) -> סטנדרט | J5: =VLOOKUP(Check[[#This Row],[טיפוס]],Tipus[],4,FALSE) -> 4H | K5: =IF(Check[[#This Row],[סטטוס2]]="הולד","פנויה",Check[[#This Row],[סטטוס2]]) -> בעלים | L5: בעלים | S5: 44040 | T5: יוסף יחזקאל | U5: 5065 | V5: 5065A | W5: 3-35 | Y5: גמר מלא- טיוב תכנון
A6: =_xlfn.CONCAT(VLOOKUP(Check[[#This Row],[סטטוס]],Sold,2,FALSE),IF(Check[[#This Row],[סטטוס]]="פנויה",IF(N6="גמר מלא סטנדרט",".GMS",IF(N6="גמר מלא טיוב חומרים",".GMC",IF(N6="גמר מינימלי",".GM",IF(N6="דירת שיווק",".DS","")))),""),".",VLOOKUP(Check[[#This Row],[טיפוס]],Tipus[],5,FALSE),".",VLOOKUP(Check[[#This Row],[מגדל]],Tower,2,FALSE),".Ap.",Check[[#This Row],[מספר דירה]]) -> S.S.2A.TS.Ap.4 | B6: =_xlfn.CONCAT(VLOOKUP(Check[[#This Row],[סטטוס]],Sold,2,FALSE),IF(Check[[#This Row],[סטטוס]]="פנויה",IF(N6="גמר מלא סטנדרט",".GMS",IF(N6="גמר מלא טיוב חומרים",".GMC",IF(N6="גמר מינימלי",".GM",IF(N6="דירת שיווק",".DS","")))),""),IF(M6="זומן לטרום",".ZLT",IF(M6="טרום מסירה",".TM",IF(M6="טרום מסירה מהנדס",".TMM",IF(M6="מסירת חזקה",".MH",IF(M6="מסירת חזקה מהנדס",".MHM",""))))),".",VLOOKUP(Check[[#This Row],[טיפוס]],Tipus[],5,FALSE),".",VLOOKUP(Check[[#This Row],[מגדל]],Tower,2,FALSE),".Ap.",Check[[#This Row],[מספר דירה]]) -> S.S.2A.TS.Ap.4 | C6: דרומי | D6: 2 | E6: 4 | F6: 201 | G6: 2A | H6: =VLOOKUP(Check[[#This Row],[טיפוס]],Tipus[],2,FALSE) -> 2 | I6: =VLOOKUP(Check[[#This Row],[טיפוס]],Tipus[],3,FALSE) -> סטנדרט | J6: =VLOOKUP(Check[[#This Row],[טיפוס]],Tipus[],4,FALSE) -> G | K6: =IF(Check[[#This Row],[סטטוס2]]="הולד","פנויה",Check[[#This Row],[סטטוס2]]) -> מכורה | L6: מכורה | S6: 44521 | T6: תומר קוקו השקעות בע"מ | Y6: דירות זוהר לוי -160 מ"ר
A7: =_xlfn.CONCAT(VLOOKUP(Check[[#This Row],[סטטוס]],Sold,2,FALSE),IF(Check[[#This Row],[סטטוס]]="פנויה",IF(N7="גמר מלא סטנדרט",".GMS",IF(N7="גמר מלא טיוב חומרים",".GMC",IF(N7="גמר מינימלי",".GM",IF(N7="דירת שיווק",".DS","")))),""),".",VLOOKUP(Check[[#This Row],[טיפוס]],Tipus[],5,FALSE),".",VLOOKUP(Check[[#This Row],[מגדל]],Tower,2,FALSE),".Ap.",Check[[#This Row],[מספר דירה]]) -> O.S.2B.TS.Ap.5 | B7: =_xlfn.CONCAT(VLOOKUP(Check[[#This Row],[סטטוס]],Sold,2,FALSE),IF(Check[[#This Row],[סטטוס]]="פנויה",IF(N7="גמר מלא סטנדרט",".GMS",IF(N7="גמר מלא טיוב חומרים",".GMC",IF(N7="גמר מינימלי",".GM",IF(N7="דירת שיווק",".DS","")))),""),IF(M7="זומן לטרום",".ZLT",IF(M7="טרום מסירה",".TM",IF(M7="טרום מסירה מהנדס",".TMM",IF(M7="מסירת חזקה",".MH",IF(M7="מסירת חזקה מהנדס",".MHM",""))))),".",VLOOKUP(Check[[#This Row],[טיפוס]],Tipus[],5,FALSE),".",VLOOKUP(Check[[#This Row],[מגדל]],Tower,2,FALSE),".Ap.",Check[[#This Row],[מספר דירה]]) -> O.S.2B.TS.Ap.5 | C7: דרומי | D7: 2 | E7: 5 | F7: 202 | G7: 2B | H7: =VLOOKUP(Check[[#This Row],[טיפוס]],Tipus[],2,FALSE) -> 2 | I7: =VLOOKUP(Check[[#This Row],[טיפוס]],Tipus[],3,FALSE) -> סטנדרט | J7: =VLOOKUP(Check[[#This Row],[טיפוס]],Tipus[],4,FALSE) -> F | K7: =IF(Check[[#This Row],[סטטוס2]]="הולד","פנויה",Check[[#This Row],[סטטוס2]]) -> בעלים | L7: בעלים | S7: 44040 | T7: טובה ראט זלצר | W7: 3-50 | Y7: דירות זוהר לוי -4 חדרים
A8: =_xlfn.CONCAT(VLOOKUP(Check[[#This Row],[סטטוס]],Sold,2,FALSE),IF(Check[[#This Row],[סטטוס]]="פנויה",IF(N8="גמר מלא סטנדרט",".GMS",IF(N8="גמר מלא טיוב חומרים",".GMC",IF(N8="גמר מינימלי",".GM",IF(N8="דירת שיווק",".DS","")))),""),".",VLOOKUP(Check[[#This Row],[טיפוס]],Tipus[],5,FALSE),".",VLOOKUP(Check[[#This Row],[מגדל]],Tower,2,FALSE),".Ap.",Check[[#This Row],[מספר דירה]]) -> O.S.2C.TS.Ap.6 | B8: =_xlfn.CONCAT(VLOOKUP(Check[[#This Row],[סטטוס]],Sold,2,FALSE),IF(Check[[#This Row],[סטטוס]]="פנויה",IF(N8="גמר מלא סטנדרט",".GMS",IF(N8="גמר מלא טיוב חומרים",".GMC",IF(N8="גמר מינימלי",".GM",IF(N8="דירת שיווק",".DS","")))),""),IF(M8="זומן לטרום",".ZLT",IF(M8="טרום מסירה",".TM",IF(M8="טרום מסירה מהנדס",".TMM",IF(M8="מסירת חזקה",".MH",IF(M8="מסירת חזקה מהנדס",".MHM",""))))),".",VLOOKUP(Check[[#This Row],[טיפוס]],Tipus[],5,FALSE),".",VLOOKUP(Check[[#This Row],[מגדל]],Tower,2,FALSE),".Ap.",Check[[#This Row],[מספר דירה]]) -> O.S.2C.TS.Ap.6 | C8: דרומי | D8: 2 | E8: 6 | F8: 203 | G8: 2C | H8: =VLOOKUP(Check[[#This Row],[טיפוס]],Tipus[],2,FALSE) -> 2 | I8: =VLOOKUP(Check[[#This Row],[טיפוס]],Tipus[],3,FALSE) -> סטנדרט | J8: =VLOOKUP(Check[[#This Row],[טיפוס]],Tipus[],4,FALSE) -> E | K8: =IF(Check[[#This Row],[סטטוס2]]="הולד","פנויה",Check[[#This Row],[סטטוס2]]) -> בעלים | L8: בעלים | S8: 44040 | T8: אברהם ברוך
A9: =_xlfn.CONCAT(VLOOKUP(Check[[#This Row],[סטטוס]],Sold,2,FALSE),IF(Check[[#This Row],[סטטוס]]="פנויה",IF(N9="גמר מלא סטנדרט",".GMS",IF(N9="גמר מלא טיוב חומרים",".GMC",IF(N9="גמר מינימלי",".GM",IF(N9="דירת שיווק",".DS","")))),""),".",VLOOKUP(Check[[#This Row],[טיפוס]],Tipus[],5,FALSE),".",VLOOKUP(Check[[#This Row],[מגדל]],Tower,2,FALSE),".Ap.",Check[[#This Row],[מספר דירה]]) -> O.S.3A.TS.Ap.7 | B9: =_xlfn.CONCAT(VLOOKUP(Check[[#This Row],[סטטוס]],Sold,2,FALSE),IF(Check[[#This Row],[סטטוס]]="פנויה",IF(N9="גמר מלא סטנדרט",".GMS",IF(N9="גמר מלא טיוב חומרים",".GMC",IF(N9="גמר מינימלי",".GM",IF(N9="דירת שיווק",".DS","")))),""),IF(M9="זומן לטרום",".ZLT",IF(M9="טרום מסירה",".TM",IF(M9="טרום מסירה מהנדס",".TMM",IF(M9="מסירת חזקה",".MH",IF(M9="מסירת חזקה מהנדס",".MHM",""))))),".",VLOOKUP(Check[[#This Row],[טיפוס]],Tipus[],5,FALSE),".",VLOOKUP(Check[[#This Row],[מגדל]],Tower,2,FALSE),".Ap.",Check[[#This Row],[מספר דירה]]) -> O.MHM.S.3A.TS.Ap.7 | C9: דרומי | D9: 2 | E9: 7 | F9: 204 | G9: 3A | H9: =VLOOKUP(Check[[#This Row],[טיפוס]],Tipus[],2,FALSE) -> 3 | I9: =VLOOKUP(Check[[#This Row],[טיפוס]],Tipus[],3,FALSE) -> סטנדרט | J9: =VLOOKUP(Check[[#This Row],[טיפוס]],Tipus[],4,FALSE) -> D | K9: =IF(Check[[#This Row],[סטטוס2]]="הולד","פנויה",Check[[#This Row],[סטטוס2]]) -> בעלים | L9: בעלים | M9: מסירת חזקה מהנדס | S9: 44040 | T9: שרון וייסמן | U9: 3217 | W9: 5-10
A10: =_xlfn.CONCAT(VLOOKUP(Check[[#This Row],[סטטוס]],Sold,2,FALSE),IF(Check[[#This Row],[סטטוס]]="פנויה",IF(N10="גמר מלא סטנדרט",".GMS",IF(N10="גמר מלא טיוב חומרים",".GMC",IF(N10="גמר מינימלי",".GM",IF(N10="דירת שיווק",".DS","")))),""),".",VLOOKUP(Check[[#This Row],[טיפוס]],Tipus[],5,FALSE),".",VLOOKUP(Check[[#This Row],[מגדל]],Tower,2,FALSE),".Ap.",Check[[#This Row],[מספר דירה]]) -> O.S.2D.TS.Ap.8 | B10: =_xlfn.CONCAT(VLOOKUP(Check[[#This Row],[סטטוס]],Sold,2,FALSE),IF(Check[[#This Row],[סטטוס]]="פנויה",IF(N10="גמר מלא סטנדרט",".GMS",IF(N10="גמר מלא טיוב חומרים",".GMC",IF(N10="גמר מינימלי",".GM",IF(N10="דירת שיווק",".DS","")))),""),IF(M10="זומן לטרום",".ZLT",IF(M10="טרום מסירה",".TM",IF(M10="טרום מסירה מהנדס",".TMM",IF(M10="מסירת חזקה",".MH",IF(M10="מסירת חזקה מהנדס",".MHM",""))))),".",VLOOKUP(Check[[#This Row],[טיפוס]],Tipus[],5,FALSE),".",VLOOKUP(Check[[#This Row],[מגדל]],Tower,2,FALSE),".Ap.",Check[[#This Row],[מספר דירה]]) -> O.S.2D.TS.Ap.8 | C10: דרומי | D10: 2 | E10: 8 | F10: 205 | G10: 2D | H10: =VLOOKUP(Check[[#This Row],[טיפוס]],Tipus[],2,FALSE) -> 2 | I10: =VLOOKUP(Check[[#This Row],[טיפוס]],Tipus[],3,FALSE) -> סטנדרט | J10: =VLOOKUP(Check[[#This Row],[טיפוס]],Tipus[],4,FALSE) -> C | K10: =IF(Check[[#This Row],[סטטוס2]]="הולד","פנויה",Check[[#This Row],[סטטוס2]]) -> בעלים | L10: בעלים | S10: 44040 | T10: מיכאל כץ
A11: =_xlfn.CONCAT(VLOOKUP(Check[[#This Row],[סטטוס]],Sold,2,FALSE),IF(Check[[#This Row],[סטטוס]]="פנויה",IF(N11="גמר מלא סטנדרט",".GMS",IF(N11="גמר מלא טיוב חומרים",".GMC",IF(N11="גמר מינימלי",".GM",IF(N11="דירת שיווק",".DS","")))),""),".",VLOOKUP(Check[[#This Row],[טיפוס]],Tipus[],5,FALSE),".",VLOOKUP(Check[[#This Row],[מגדל]],Tower,2,FALSE),".Ap.",Check[[#This Row],[מספר דירה]]) -> V.GMS.S.2E.TS.Ap.9 | B11: =_xlfn.CONCAT(VLOOKUP(Check[[#This Row],[סטטוס]],Sold,2,FALSE),IF(Check[[#This Row],[סטטוס]]="פנויה",IF(N11="גמר מלא סטנדרט",".GMS",IF(N11="גמר מלא טיוב חומרים",".GMC",IF(N11="גמר מינימלי",".GM",IF(N11="דירת שיווק",".DS","")))),""),IF(M11="זומן לטרום",".ZLT",IF(M11="טרום מסירה",".TM",IF(M11="טרום מסירה מהנדס",".TMM",IF(M11="מסירת חזקה",".MH",IF(M11="מסירת חזקה מהנדס",".MHM",""))))),".",VLOOKUP(Check[[#This Row],[טיפוס]],Tipus[],5,FALSE),".",VLOOKUP(Check[[#This Row],[מגדל]],Tower,2,FALSE),".Ap.",Check[[#This Row],[מספר דירה]]) -> V.GMS.MH.S.2E.TS.Ap.9 | C11: דרומי | D11: 2 | E11: 9 | F11: 206 | G11: 2E | H11: =VLOOKUP(Check[[#This Row],[טיפוס]],Tipus[],2,FALSE) -> 2 | I11: =VLOOKUP(Check[[#This Row],[טיפוס]],Tipus[],3,FALSE) -> סטנדרט | J11: =VLOOKUP(Check[[#This Row],[טיפוס]],Tipus[],4,FALSE) -> B | K11: =IF(Check[[#This Row],[סטטוס2]]="הולד","פנויה",Check[[#This Row],[סטטוס2]]) -> פנויה | L11: פנויה | M11: מסירת חזקה | N11: גמר מלא סטנדרט | O11: יש תוכניות ובחירת גמר עפ"י שיחה עם אלון | P11: יש בחירות ותוכניות
A12: =_xlfn.CONCAT(VLOOKUP(Check[[#This Row],[סטטוס]],Sold,2,FALSE),IF(Check[[#This Row],[סטטוס]]="פנויה",IF(N12="גמר מלא סטנדרט",".GMS",IF(N12="גמר מלא טיוב חומרים",".GMC",IF(N12="גמר מינימלי",".GM",IF(N12="דירת שיווק",".DS","")))),""),".",VLOOKUP(Check[[#This Row],[טיפוס]],Tipus[],5,FALSE),".",VLOOKUP(Check[[#This Row],[מגדל]],Tower,2,FALSE),".Ap.",Check[[#This Row],[מספר דירה]]) -> V.GMS.S.2F.TS.Ap.10 | B12: =_xlfn.CONCAT(VLOOKUP(Check[[#This Row],[סטטוס]],Sold,2,FALSE),IF(Check[[#This Row],[סטטוס]]="פנויה",IF(N12="גמר מלא סטנדרט",".GMS",IF(N12="גמר מלא טיוב חומרים",".GMC",IF(N12="גמר מינימלי",".GM",IF(N12="דירת שיווק",".DS","")))),""),IF(M12="זומן לטרום",".ZLT",IF(M12="טרום מסירה",".TM",IF(M12="טרום מסירה מהנדס",".TMM",IF(M12="מסירת חזקה",".MH",IF(M12="מסירת חזקה מהנדס",".MHM",""))))),".",VLOOKUP(Check[[#This Row],[טיפוס]],Tipus[],5,FALSE),".",VLOOKUP(Check[[#This Row],[מגדל]],Tower,2,FALSE),".Ap.",Check[[#This Row],[מספר דירה]]) -> V.GMS.S.2F.TS.Ap.10 | C12: דרומי | D12: 2 | E12: 10 | F12: 207 | G12: 2F | H12: =VLOOKUP(Check[[#This Row],[טיפוס]],Tipus[],2,FALSE) -> 2 | I12: =VLOOKUP(Check[[#This Row],[טיפוס]],Tipus[],3,FALSE) -> סטנדרט | J12: =VLOOKUP(Check[[#This Row],[טיפוס]],Tipus[],4,FALSE) -> A | K12: =IF(Check[[#This Row],[סטטוס2]]="הולד","פנויה",Check[[#This Row],[סטטוס2]]) -> פנויה | L12: פנויה | N12: גמר מלא סטנדרט | O12: יש תוכניות ובחירת גמר עפ"י שיחה עם אלון | P12: יש בחירות ותוכניות
A13: =_xlfn.CONCAT(VLOOKUP(Check[[#This Row],[סטטוס]],Sold,2,FALSE),IF(Check[[#This Row],[סטטוס]]="פנויה",IF(N13="גמר מלא סטנדרט",".GMS",IF(N13="גמר מלא טיוב חומרים",".GMC",IF(N13="גמר מינימלי",".GM",IF(N13="דירת שיווק",".DS","")))),""),".",VLOOKUP(Check[[#This Row],[טיפוס]],Tipus[],5,FALSE),".",VLOOKUP(Check[[#This Row],[מגדל]],Tower,2,FALSE),".Ap.",Check[[#This Row],[מספר דירה]]) -> S.S.2A.TS.Ap.11 | B13: =_xlfn.CONCAT(VLOOKUP(Check[[#This Row],[סטטוס]],Sold,2,FALSE),IF(Check[[#This Row],[סטטוס]]="פנויה",IF(N13="גמר מלא סטנדרט",".GMS",IF(N13="גמר מלא טיוב חומרים",".GMC",IF(N13="גמר מינימלי",".GM",IF(N13="דירת שיווק",".DS","")))),""),IF(M13="זומן לטרום",".ZLT",IF(M13="טרום מסירה",".TM",IF(M13="טרום מסירה מהנדס",".TMM",IF(M13="מסירת חזקה",".MH",IF(M13="מסירת חזקה מהנדס",".MHM",""))))),".",VLOOKUP(Check[[#This Row],[טיפוס]],Tipus[],5,FALSE),".",VLOOKUP(Check[[#This Row],[מגדל]],Tower,2,FALSE),".Ap.",Check[[#This Row],[מספר דירה]]) -> S.S.2A.TS.Ap.11 | C13: דרומי | D13: 3 | E13: 11 | F13: 301 | G13: 2A | H13: =VLOOKUP(Check[[#This Row],[טיפוס]],Tipus[],2,FALSE) -> 2 | I13: =VLOOKUP(Check[[#This Row],[טיפוס]],Tipus[],3,FALSE) -> סטנדרט | J13: =VLOOKUP(Check[[#This Row],[טיפוס]],Tipus[],4,FALSE) -> G | K13: =IF(Check[[#This Row],[סטטוס2]]="הולד","פנויה",Check[[#This Row],[סטטוס2]]) -> מכורה | L13: מכורה | S13: 44521 | T13: תומר קוקו השקעות בע"מ
A14: =_xlfn.CONCAT(VLOOKUP(Check[[#This Row],[סטטוס]],Sold,2,FALSE),IF(Check[[#This Row],[סטטוס]]="פנויה",IF(N14="גמר מלא סטנדרט",".GMS",IF(N14="גמר מלא טיוב חומרים",".GMC",IF(N14="גמר מינימלי",".GM",IF(N14="דירת שיווק",".DS","")))),""),".",VLOOKUP(Check[[#This Row],[טיפוס]],Tipus[],5,FALSE),".",VLOOKUP(Check[[#This Row],[מגדל]],Tower,2,FALSE),".Ap.",Check[[#This Row],[מספר דירה]]) -> S.S.2B.TS.Ap.12 | B14: =_xlfn.CONCAT(VLOOKUP(Check[[#This Row],[סטטוס]],Sold,2,FALSE),IF(Check[[#This Row],[סטטוס]]="פנויה",IF(N14="גמר מלא סטנדרט",".GMS",IF(N14="גמר מלא טיוב חומרים",".GMC",IF(N14="גמר מינימלי",".GM",IF(N14="דירת שיווק",".DS","")))),""),IF(M14="זומן לטרום",".ZLT",IF(M14="טרום מסירה",".TM",IF(M14="טרום מסירה מהנדס",".TMM",IF(M14="מסירת חזקה",".MH",IF(M14="מסירת חזקה מהנדס",".MHM",""))))),".",VLOOKUP(Check[[#This Row],[טיפוס]],Tipus[],5,FALSE),".",VLOOKUP(Check[[#This Row],[מגדל]],Tower,2,FALSE),".Ap.",Check[[#This Row],[מספר דירה]]) -> S.TM.S.2B.TS.Ap.12 | C14: דרומי | D14: 3 | E14: 12 | F14: 302 | G14: 2B | H14: =VLOOKUP(Check[[#This Row],[טיפוס]],Tipus[],2,FALSE) -> 2 | I14: =VLOOKUP(Check[[#This Row],[טיפוס]],Tipus[],3,FALSE) -> סטנדרט | J14: =VLOOKUP(Check[[#This Row],[טיפוס]],Tipus[],4,FALSE) -> F | K14: =IF(Check[[#This Row],[סטטוס2]]="הולד","פנויה",Check[[#This Row],[סטטוס2]]) -> מכורה | L14: מכורה | M14: טרום מסירה | S14: 45358 | T14: בורוכוביץ אנגלה ויחזקאל
A15: =_xlfn.CONCAT(VLOOKUP(Check[[#This Row],[סטטוס]],Sold,2,FALSE),IF(Check[[#This Row],[סטטוס]]="פנויה",IF(N15="גמר מלא סטנדרט",".GMS",IF(N15="גמר מלא טיוב חומרים",".GMC",IF(N15="גמר מינימלי",".GM",IF(N15="דירת שיווק",".DS","")))),""),".",VLOOKUP(Check[[#This Row],[טיפוס]],Tipus[],5,FALSE),".",VLOOKUP(Check[[#This Row],[מגדל]],Tower,2,FALSE),".Ap.",Check[[#This Row],[מספר דירה]]) -> S.S.2C.TS.Ap.13 | B15: =_xlfn.CONCAT(VLOOKUP(Check[[#This Row],[סטטוס]],Sold,2,FALSE),IF(Check[[#This Row],[סטטוס]]="פנויה",IF(N15="גמר מלא סטנדרט",".GMS",IF(N15="גמר מלא טיוב חומרים",".GMC",IF(N15="גמר מינימלי",".GM",IF(N15="דירת שיווק",".DS","")))),""),IF(M15="זומן לטרום",".ZLT",IF(M15="טרום מסירה",".TM",IF(M15="טרום מסירה מהנדס",".TMM",IF(M15="מסירת חזקה",".MH",IF(M15="מסירת חזקה מהנדס",".MHM",""))))),".",VLOOKUP(Check[[#This Row],[טיפוס]],Tipus[],5,FALSE),".",VLOOKUP(Check[[#This Row],[מגדל]],Tower,2,FALSE),".Ap.",Check[[#This Row],[מספר דירה]]) -> S.TM.S.2C.TS.Ap.13 | C15: דרומי | D15: 3 | E15: 13 | F15: 303 | G15: 2C | H15: =VLOOKUP(Check[[#This Row],[טיפוס]],Tipus[],2,FALSE) -> 2 | I15: =VLOOKUP(Check[[#This Row],[טיפוס]],Tipus[],3,FALSE) -> סטנדרט | J15: =VLOOKUP(Check[[#This Row],[טיפוס]],Tipus[],4,FALSE) -> E | K15: =IF(Check[[#This Row],[סטטוס2]]="הולד","פנויה",Check[[#This Row],[סטטוס2]]) -> מכורה | L15: מכורה | M15: טרום מסירה | S15: 44762 | T15: ברקן גולן, שחר גולן
A16: =_xlfn.CONCAT(VLOOKUP(Check[[#This Row],[סטטוס]],Sold,2,FALSE),IF(Check[[#This Row],[סטטוס]]="פנויה",IF(N16="גמר מלא סטנדרט",".GMS",IF(N16="גמר מלא טיוב חומרים",".GMC",IF(N16="גמר מינימלי",".GM",IF(N16="דירת שיווק",".DS","")))),""),".",VLOOKUP(Check[[#This Row],[טיפוס]],Tipus[],5,FALSE),".",VLOOKUP(Check[[#This Row],[מגדל]],Tower,2,FALSE),".Ap.",Check[[#This Row],[מספר דירה]]) -> O.S.3A.TS.Ap.14 | B16: =_xlfn.CONCAT(VLOOKUP(Check[[#This Row],[סטטוס]],Sold,2,FALSE),IF(Check[[#This Row],[סטטוס]]="פנויה",IF(N16="גמר מלא סטנדרט",".GMS",IF(N16="גמר מלא טיוב חומרים",".GMC",IF(N16="גמר מינימלי",".GM",IF(N16="דירת שיווק",".DS","")))),""),IF(M16="זומן לטרום",".ZLT",IF(M16="טרום מסירה",".TM",IF(M16="טרום מסירה מהנדס",".TMM",IF(M16="מסירת חזקה",".MH",IF(M16="מסירת חזקה מהנדס",".MHM",""))))),".",VLOOKUP(Check[[#This Row],[טיפוס]],Tipus[],5,FALSE),".",VLOOKUP(Check[[#This Row],[מגדל]],Tower,2,FALSE),".Ap.",Check[[#This Row],[מספר דירה]]) -> O.TM.S.3A.TS.Ap.14 | C16: דרומי | D16: 3 | E16: 14 | F16: 304 | G16: 3A | H16: =VLOOKUP(Check[[#This Row],[טיפוס]],Tipus[],2,FALSE) -> 3 | I16: =VLOOKUP(Check[[#This Row],[טיפוס]],Tipus[],3,FALSE) -> סטנדרט | J16: =VLOOKUP(Check[[#This Row],[טיפוס]],Tipus[],4,FALSE) -> D | K16: =IF(Check[[#This Row],[סטטוס2]]="הולד","פנויה",Check[[#This Row],[סטטוס2]]) -> בעלים | L16: בעלים | M16: טרום מסירה | S16: 44040 | T16: ניסים ניר אלקלעי, מירב אלקלעי | U16: 3216 | W16: 5-10
A17: =_xlfn.CONCAT(VLOOKUP(Check[[#This Row],[סטטוס]],Sold,2,FALSE),IF(Check[[#This Row],[סטטוס]]="פנויה",IF(N17="גמר מלא סטנדרט",".GMS",IF(N17="גמר מלא טיוב חומרים",".GMC",IF(N17="גמר מינימלי",".GM",IF(N17="דירת שיווק",".DS","")))),""),".",VLOOKUP(Check[[#This Row],[טיפוס]],Tipus[],5,FALSE),".",VLOOKUP(Check[[#This Row],[מגדל]],Tower,2,FALSE),".Ap.",Check[[#This Row],[מספר דירה]]) -> S.S.2D.TS.Ap.15 | B17: =_xlfn.CONCAT(VLOOKUP(Check[[#This Row],[סטטוס]],Sold,2,FALSE),IF(Check[[#This Row],[סטטוס]]="פנויה",IF(N17="גמר מלא סטנדרט",".GMS",IF(N17="גמר מלא טיוב חומרים",".GMC",IF(N17="גמר מינימלי",".GM",IF(N17="דירת שיווק",".DS","")))),""),IF(M17="זומן לטרום",".ZLT",IF(M17="טרום מסירה",".TM",IF(M17="טרום מסירה מהנדס",".TMM",IF(M17="מסירת חזקה",".MH",IF(M17="מסירת חזקה מהנדס",".MHM",""))))),".",VLOOKUP(Check[[#This Row],[טיפוס]],Tipus[],5,FALSE),".",VLOOKUP(Check[[#This Row],[מגדל]],Tower,2,FALSE),".Ap.",Check[[#This Row],[מספר דירה]]) -> S.TM.S.2D.TS.Ap.15 | C17: דרומי | D17: 3 | E17: 15 | F17: 305 | G17: 2D | H17: =VLOOKUP(Check[[#This Row],[טיפוס]],Tipus[],2,FALSE) -> 2 | I17: =VLOOKUP(Check[[#This Row],[טיפוס]],Tipus[],3,FALSE) -> סטנדרט | J17: =VLOOKUP(Check[[#This Row],[טיפוס]],Tipus[],4,FALSE) -> C | K17: =IF(Check[[#This Row],[סטטוס2]]="הולד","פנויה",Check[[#This Row],[סטטוס2]]) -> מכורה | L17: מכורה | M17: טרום מסירה | S17: 44527 | T17: נילי אופק נכסים בע"מ
A18: =_xlfn.CONCAT(VLOOKUP(Check[[#This Row],[סטטוס]],Sold,2,FALSE),IF(Check[[#This Row],[סטטוס]]="פנויה",IF(N18="גמר מלא סטנדרט",".GMS",IF(N18="גמר מלא טיוב חומרים",".GMC",IF(N18="גמר מינימלי",".GM",IF(N18="דירת שיווק",".DS","")))),""),".",VLOOKUP(Check[[#This Row],[טיפוס]],Tipus[],5,FALSE),".",VLOOKUP(Check[[#This Row],[מגדל]],Tower,2,FALSE),".Ap.",Check[[#This Row],[מספר דירה]]) -> V.GMS.S.2E.TS.Ap.16 | B18: =_xlfn.CONCAT(VLOOKUP(Check[[#This Row],[סטטוס]],Sold,2,FALSE),IF(Check[[#This Row],[סטטוס]]="פנויה",IF(N18="גמר מלא סטנדרט",".GMS",IF(N18="גמר מלא טיוב חומרים",".GMC",IF(N18="גמר מינימלי",".GM",IF(N18="דירת שיווק",".DS","")))),""),IF(M18="זומן לטרום",".ZLT",IF(M18="טרום מסירה",".TM",IF(M18="טרום מסירה מהנדס",".TMM",IF(M18="מסירת חזקה",".MH",IF(M18="מסירת חזקה מהנדס",".MHM",""))))),".",VLOOKUP(Check[[#This Row],[טיפוס]],Tipus[],5,FALSE),".",VLOOKUP(Check[[#This Row],[מגדל]],Tower,2,FALSE),".Ap.",Check[[#This Row],[מספר דירה]]) -> V.GMS.S.2E.TS.Ap.16 | C18: דרומי | D18: 3 | E18: 16 | F18: 306 | G18: 2E | H18: =VLOOKUP(Check[[#This Row],[טיפוס]],Tipus[],2,FALSE) -> 2 | I18: =VLOOKUP(Check[[#This Row],[טיפוס]],Tipus[],3,FALSE) -> סטנדרט | J18: =VLOOKUP(Check[[#This Row],[טיפוס]],Tipus[],4,FALSE) -> B | K18: =IF(Check[[#This Row],[סטטוס2]]="הולד","פנויה",Check[[#This Row],[סטטוס2]]) -> פנויה | L18: פנויה | N18: גמר מלא סטנדרט | O18: יש תוכניות ובחירת גמר עפ"י שיחה עם אלון | P18: יש בחירות ותוכניות
A19: =_xlfn.CONCAT(VLOOKUP(Check[[#This Row],[סטטוס]],Sold,2,FALSE),IF(Check[[#This Row],[סטטוס]]="פנויה",IF(N19="גמר מלא סטנדרט",".GMS",IF(N19="גמר מלא טיוב חומרים",".GMC",IF(N19="גמר מינימלי",".GM",IF(N19="דירת שיווק",".DS","")))),""),".",VLOOKUP(Check[[#This Row],[טיפוס]],Tipus[],5,FALSE),".",VLOOKUP(Check[[#This Row],[מגדל]],Tower,2,FALSE),".Ap.",Check[[#This Row],[מספר דירה]]) -> O.S.2F.TS.Ap.17 | B19: =_xlfn.CONCAT(VLOOKUP(Check[[#This Row],[סטטוס]],Sold,2,FALSE),IF(Check[[#This Row],[סטטוס]]="פנויה",IF(N19="גמר מלא סטנדרט",".GMS",IF(N19="גמר מלא טיוב חומרים",".GMC",IF(N19="גמר מינימלי",".GM",IF(N19="דירת שיווק",".DS","")))),""),IF(M19="זומן לטרום",".ZLT",IF(M19="טרום מסירה",".TM",IF(M19="טרום מסירה מהנדס",".TMM",IF(M19="מסירת חזקה",".MH",IF(M19="מסירת חזקה מהנדס",".MHM",""))))),".",VLOOKUP(Check[[#This Row],[טיפוס]],Tipus[],5,FALSE),".",VLOOKUP(Check[[#This Row],[מגדל]],Tower,2,FALSE),".Ap.",Check[[#This Row],[מספר דירה]]) -> O.TM.S.2F.TS.Ap.17 | C19: דרומי | D19: 3 | E19: 17 | F19: 307 | G19: 2F | H19: =VLOOKUP(Check[[#This Row],[טיפוס]],Tipus[],2,FALSE) -> 2 | I19: =VLOOKUP(Check[[#This Row],[טיפוס]],Tipus[],3,FALSE) -> סטנדרט | J19: =VLOOKUP(Check[[#This Row],[טיפוס]],Tipus[],4,FALSE) -> A | K19: =IF(Check[[#This Row],[סטטוס2]]="הולד","פנויה",Check[[#This Row],[סטטוס2]]) -> בעלים | L19: בעלים | M19: טרום מסירה | S19: 44040 | T19: דוריס רבה | U19: 4200
A20: =_xlfn.CONCAT(VLOOKUP(Check[[#This Row],[סטטוס]],Sold,2,FALSE),IF(Check[[#This Row],[סטטוס]]="פנויה",IF(N20="גמר מלא סטנדרט",".GMS",IF(N20="גמר מלא טיוב חומרים",".GMC",IF(N20="גמר מינימלי",".GM",IF(N20="דירת שיווק",".DS","")))),""),".",VLOOKUP(Check[[#This Row],[טיפוס]],Tipus[],5,FALSE),".",VLOOKUP(Check[[#This Row],[מגדל]],Tower,2,FALSE),".Ap.",Check[[#This Row],[מספר דירה]]) -> V.GMS.S.4A.TS.Ap.18 | B20: =_xlfn.CONCAT(VLOOKUP(Check[[#This Row],[סטטוס]],Sold,2,FALSE),IF(Check[[#This Row],[סטטוס]]="פנויה",IF(N20="גמר מלא סטנדרט",".GMS",IF(N20="גמר מלא טיוב חומרים",".GMC",IF(N20="גמר מינימלי",".GM",IF(N20="דירת שיווק",".DS","")))),""),IF(M20="זומן לטרום",".ZLT",IF(M20="טרום מסירה",".TM",IF(M20="טרום מסירה מהנדס",".TMM",IF(M20="מסירת חזקה",".MH",IF(M20="מסירת חזקה מהנדס",".MHM",""))))),".",VLOOKUP(Check[[#This Row],[טיפוס]],Tipus[],5,FALSE),".",VLOOKUP(Check[[#This Row],[מגדל]],Tower,2,FALSE),".Ap.",Check[[#This Row],[מספר דירה]]) -> V.GMS.S.4A.TS.Ap.18 | C20: דרומי | D20: 3 | E20: 18 | F20: 308 | G20: 4A | H20: =VLOOKUP(Check[[#This Row],[טיפוס]],Tipus[],2,FALSE) -> 4 | I20: =VLOOKUP(Check[[#This Row],[טיפוס]],Tipus[],3,FALSE) -> סטנדרט | J20: =VLOOKUP(Check[[#This Row],[טיפוס]],Tipus[],4,FALSE) -> J | K20: =IF(Check[[#This Row],[סטטוס2]]="הולד","פנויה",Check[[#This Row],[סטטוס2]]) -> פנויה | L20: פנויה | N20: גמר מלא סטנדרט | O20: יש תוכניות ובחירת גמר עפ"י שיחה עם אלון | P20: יש בחירות ותוכניות
A21: =_xlfn.CONCAT(VLOOKUP(Check[[#This Row],[סטטוס]],Sold,2,FALSE),IF(Check[[#This Row],[סטטוס]]="פנויה",IF(N21="גמר מלא סטנדרט",".GMS",IF(N21="גמר מלא טיוב חומרים",".GMC",IF(N21="גמר מינימלי",".GM",IF(N21="דירת שיווק",".DS","")))),""),".",VLOOKUP(Check[[#This Row],[טיפוס]],Tipus[],5,FALSE),".",VLOOKUP(Check[[#This Row],[מגדל]],Tower,2,FALSE),".Ap.",Check[[#This Row],[מספר דירה]]) -> O.S.2G.TS.Ap.19 | B21: =_xlfn.CONCAT(VLOOKUP(Check[[#This Row],[סטטוס]],Sold,2,FALSE),IF(Check[[#This Row],[סטטוס]]="פנויה",IF(N21="גמר מלא סטנדרט",".GMS",IF(N21="גמר מלא טיוב חומרים",".GMC",IF(N21="גמר מינימלי",".GM",IF(N21="דירת שיווק",".DS","")))),""),IF(M21="זומן לטרום",".ZLT",IF(M21="טרום מסירה",".TM",IF(M21="טרום מסירה מהנדס",".TMM",IF(M21="מסירת חזקה",".MH",IF(M21="מסירת חזקה מהנדס",".MHM",""))))),".",VLOOKUP(Check[[#This Row],[טיפוס]],Tipus[],5,FALSE),".",VLOOKUP(Check[[#This Row],[מגדל]],Tower,2,FALSE),".Ap.",Check[[#This Row],[מספר דירה]]) -> O.TM.S.2G.TS.Ap.19 | C21: דרומי | D21: 3 | E21: 19 | F21: 309 | G21: 2G | H21: =VLOOKUP(Check[[#This Row],[טיפוס]],Tipus[],2,FALSE) -> 2 | I21: =VLOOKUP(Check[[#This Row],[טיפוס]],Tipus[],3,FALSE) -> סטנדרט | J21: =VLOOKUP(Check[[#This Row],[טיפוס]],Tipus[],4,FALSE) -> I | K21: =IF(Check[[#This Row],[סטטוס2]]="הולד","פנויה",Check[[#This Row],[סטטוס2]]) -> בעלים | L21: בעלים | M21: טרום מסירה | S21: 44040 | T21: מנחם משה זלצר, גילת זלצר | U21: 4196
A22: =_xlfn.CONCAT(VLOOKUP(Check[[#This Row],[סטטוס]],Sold,2,FALSE),IF(Check[[#This Row],[סטטוס]]="פנויה",IF(N22="גמר מלא סטנדרט",".GMS",IF(N22="גמר מלא טיוב חומרים",".GMC",IF(N22="גמר מינימלי",".GM",IF(N22="דירת שיווק",".DS","")))),""),".",VLOOKUP(Check[[#This Row],[טיפוס]],Tipus[],5,FALSE),".",VLOOKUP(Check[[#This Row],[מגדל]],Tower,2,FALSE),".Ap.",Check[[#This Row],[מספר דירה]]) -> V.GMS.S.4B.TS.Ap.20 | B22: =_xlfn.CONCAT(VLOOKUP(Check[[#This Row],[סטטוס]],Sold,2,FALSE),IF(Check[[#This Row],[סטטוס]]="פנויה",IF(N22="גמר מלא סטנדרט",".GMS",IF(N22="גמר מלא טיוב חומרים",".GMC",IF(N22="גמר מינימלי",".GM",IF(N22="דירת שיווק",".DS","")))),""),IF(M22="זומן לטרום",".ZLT",IF(M22="טרום מסירה",".TM",IF(M22="טרום מסירה מהנדס",".TMM",IF(M22="מסירת חזקה",".MH",IF(M22="מסירת חזקה מהנדס",".MHM",""))))),".",VLOOKUP(Check[[#This Row],[טיפוס]],Tipus[],5,FALSE),".",VLOOKUP(Check[[#This Row],[מגדל]],Tower,2,FALSE),".Ap.",Check[[#This Row],[מספר דירה]]) -> V.GMS.S.4B.TS.Ap.20 | C22: דרומי | D22: 3 | E22: 20 | F22: 310 | G22: 4B | H22: =VLOOKUP(Check[[#This Row],[טיפוס]],Tipus[],2,FALSE) -> 4 | I22: =VLOOKUP(Check[[#This Row],[טיפוס]],Tipus[],3,FALSE) -> סטנדרט | J22: =VLOOKUP(Check[[#This Row],[טיפוס]],Tipus[],4,FALSE) -> H | K22: =IF(Check[[#This Row],[סטטוס2]]="הולד","פנויה",Check[[#This Row],[סטטוס2]]) -> פנויה | L22: פנויה | N22: גמר מלא סטנדרט | O22: יש תוכניות ובחירת גמר עפ"י שיחה עם אלון | P22: יש בחירות ותוכניות
A23: =_xlfn.CONCAT(VLOOKUP(Check[[#This Row],[סטטוס]],Sold,2,FALSE),IF(Check[[#This Row],[סטטוס]]="פנויה",IF(N23="גמר מלא סטנדרט",".GMS",IF(N23="גמר מלא טיוב חומרים",".GMC",IF(N23="גמר מינימלי",".GM",IF(N23="דירת שיווק",".DS","")))),""),".",VLOOKUP(Check[[#This Row],[טיפוס]],Tipus[],5,FALSE),".",VLOOKUP(Check[[#This Row],[מגדל]],Tower,2,FALSE),".Ap.",Check[[#This Row],[מספר דירה]]) -> O.S.2A.TS.Ap.21 | B23: =_xlfn.CONCAT(VLOOKUP(Check[[#This Row],[סטטוס]],Sold,2,FALSE),IF(Check[[#This Row],[סטטוס]]="פנויה",IF(N23="גמר מלא סטנדרט",".GMS",IF(N23="גמר מלא טיוב חומרים",".GMC",IF(N23="גמר מינימלי",".GM",IF(N23="דירת שיווק",".DS","")))),""),IF(M23="זומן לטרום",".ZLT",IF(M23="טרום מסירה",".TM",IF(M23="טרום מסירה מהנדס",".TMM",IF(M23="מסירת חזקה",".MH",IF(M23="מסירת חזקה מהנדס",".MHM",""))))),".",VLOOKUP(Check[[#This Row],[טיפוס]],Tipus[],5,FALSE),".",VLOOKUP(Check[[#This Row],[מגדל]],Tower,2,FALSE),".Ap.",Check[[#This Row],[מספר דירה]]) -> O.S.2A.TS.Ap.21 | C23: דרומי | D23: 4 | E23: 21 | F23: 401 | G23: 2A | H23: =VLOOKUP(Check[[#This Row],[טיפוס]],Tipus[],2,FALSE) -> 2 | I23: =VLOOKUP(Check[[#This Row],[טיפוס]],Tipus[],3,FALSE) -> סטנדרט | J23: =VLOOKUP(Check[[#This Row],[טיפוס]],Tipus[],4,FALSE) -> G | K23: =IF(Check[[#This Row],[סטטוס2]]="הולד","פנויה",Check[[#This Row],[סטטוס2]]) -> בעלים | L23: בעלים | S23: 44040 | T23: א.ס.ש השקעות בע"מ | U23: 4197
